Workbook

Sheet 云盘-原始
A1: 工号-新 | B1: 部门 | C1: 中心 | D1: 岗位 | E1: 姓名 | F1: 考核目标 | G1: 实际完成 | H1: 完成率 | I1: 权重 | J1: 目标得分 | K1: 总完成率 | L1: 总得分 | M1: 总奖金 | N1: 绩效基数 | O1: 奖金系数 | P1: 车补天数 | Q1: 车补 | R1: 备注 | S1: 排名 | T1: 排名系数 | U1: 奖金池总额 | V1: 奖金池绩效 | W1: 绩效奖金
A2: FD-071139 | B2: 线下渠道部 | D2: 督导 | E2: 王冬梅 | F2: 活动POS目标 500000 | G2: 1037582.8 | H2: 2.0751656 | I2: 0.35 | K2: 1.7077429 | L2: 1.5 | M2: 4050 | N2: 3000 | O2: 1.35 | P2: 24 | Q2: 384
B3: 线下渠道部 | D3: 督导 | F3: 个人pos目标 38000 | G3: 60521.51 | H3: 1.5926713 | I3: 0.35 | L3: 1.5
B4: 线下渠道部 | D4: 督导 | F4: 总部演讲考核 1 | G4: 1 | H4: 1 | I4: 0.1 | L4: 1
B5: 线下渠道部 | D5: 督导 | F5: 线下培训考核 5 | G5: 8.1 | H5: 1.62 | I5: 0.2 | L5: 1.5
A6: FD-074553 | B6: 线下渠道部 | D6: 督导 | E6: 王娜 | F6: 活动POS目标 500000 | G6: 851012 | H6: 1.702024 | I6: 0.35 | K6: 1.5428642 | L6: 1.5 | M6: 3000 | N6: 3000 | O6: 1 | P6: 27 | Q6: 432
B7: 线下渠道部 | D7: 督导 | F7: 个人pos目标 38000 | G7: 57234.06 | H7: 1.5061595 | I7: 0.35 | L7: 1.5
B8: 线下渠道部 | D8: 督导 | F8: 总部演讲考核 1 | G8: 1.5 | H8: 1.5 | I8: 0.1 | L8: 1.5
B9: 线下渠道部 | D9: 督导 | F9: 线下培训考核 5 | G9: 6.75 | H9: 1.35 | I9: 0.2 | L9: 1.2
A10: FD-078246 | B10: 线下渠道部 | D10: 督导 | E10: 张婷 | F10: 活动POS目标 500000 | G10: 760591.4 | H10: 1.5211828 | I10: 0.35 | K10: 1.4778811 | L10: 1.5 | M10: 3000 | N10: 3000 | O10: 1 | P10: 27 | Q10: 432
B11: 线下渠道部 | D11: 督导 | F11: 个人pos目标 38000 | G11: 60742.14 | H11: 1.5984774 | I11: 0.35 | L11: 1.5
B12: 线下渠道部 | D12: 督导 | F12: 总部演讲考核 1 | G12: 0.8 | H12: 0.8 | I12: 0.1 | L12: 0.8
B13: 线下渠道部 | D13: 督导 | F13: 线下培训考核 5 | G13: 7.65 | H13: 1.53 | I13: 0.2 | L13: 1.5
A14: 外包督导 | B14: 线下渠道部 | D14: 督导 | E14: 时美娟 | F14: 活动POS目标 500000 | G14: 853560.43 | H14: 1.7071209 | I14: 0.35 | K14: 1.5809081 | L14: 1.5 | M14: 2400 | N14: 3000 | O14: 0.8
B15: 线下渠道部 | D15: 督导 | F15: 个人pos目标 38000 | G15: 64428 | H15: 1.6954737 | I15: 0.35 | L15: 1.5
B16: 线下渠道部 | D16: 督导 | F16: 总部演讲考核 1 | G16: 1.2 | H16: 1.2 | I16: 0.1 | L16: 1.2
B17: 线下渠道部 | D17: 督导 | F17: 线下培训考核 5 | G17: 6.75 | H17: 1.35 | I17: 0.2 | L17: 1.2
A18: FD-077555 | B18: 线下渠道部 | D18: 督导 | E18: 王琳 | F18: 活动POS目标 500000 | G18: 844581.7 | H18: 1.6891634 | I18: 0.35 | K18: 1.5296934 | L18: 1.5 | M18: 4050 | N18: 3000 | O18: 1.35 | P18: 29 | Q18: 464
B19: 线下渠道部 | D19: 督导 | F19: 个人pos目标 38000 | G19: 58029.93 | H19: 1.5271034 | I19: 0.35 | L19: 1.5
B20: 线下渠道部 | D20: 督导 | F20: 总部演讲考核 1 | G20: 1 | H20: 1 | I20: 0.1 | L20: 1
B21: 线下渠道部 | D21: 督导 | F21: 线下培训考核 5 | G21: 7.6 | H21: 1.52 | I21: 0.2 | L21: 1.5
A22: 外包督导 | B22: 线下渠道部 | D22: 督导 | E22: 刘茜 | F22: 活动POS目标 500000 | G22: 833877.42 | H22: 1.6677548 | I22: 0.35 | K22: 1.4989692 | L22: 1.5 | M22: 1500 | N22: 3000 | O22: 0.5
B23: 线下渠道部 | D23: 督导 | F23: 个人pos目标 38000 | G23: 61587.69 | H23: 1.6207287 | I23: 0.35 | L23: 1.5
B24: 线下渠道部 | D24: 督导 | F24: 总部演讲考核 1 | G24: 0.5 | H24: 0.5 | I24: 0.1 | L24: 0.5
B25: 线下渠道部 | D25: 督导 | F25: 线下培训考核 5 | G25: 7.45 | H25: 1.49 | I25: 0.2 | L25: 1.2
A26: FD-078109 | B26: 线下渠道部 | E26: 许元元 | Q26: 460
A27: FD-070643 | B27: 线下渠道部 | E27: 罗静文 | Q27: 500
A28: FD-078387 | B28: 线下渠道部 | E28: 李宏庆 | Q28: 420
A29: FD-076847 | B29: 线下渠道部 | E29: 蒋冰清 | Q29: 300
A30: FD-078748 | B30: 线下渠道部 | E30: 杨敏 | Q30: 500
A31: FD-070181 | B31: 线下渠道部 | E31: 梁倩雯 | Q31: 360
A32: FD-079435 | B32: 线下渠道部 | E32: 热夏提·古尔班江 | Q32: 460
A33: FD-070780 | B33: 线下渠道部 | E33: 黄策 | Q33: 380
A34: FD-074038 | B34: 线下渠道部 | E34: 黄慧琳 | Q34: 440
A35: FD-072418 | B35: 线下渠道部 | E35: 马诗瑾 | Q35: 340
A36: FD-076987 | B36: 线下渠道部 | E36: 孙海诺 | Q36: 340
A37: FD-075526 | B37: 线下渠道部 | E37: 夏星泽 | Q37: 576
... A39: FD-075978 | B39: 线下渠道部 | E39: 赵海宝 | Q39: 200
A40: FD-070915 | B40: 线下渠道部 | E40: 吴雪玲 | M40: 1800 | N40: 4000 | O40: 0.3 | R40: 当月绩效3600，5月6月绩效调整额-1800，计算后为1800
B41: 产品供应部 | D41: 主管 | E41: 李炜瑶 | F41: 货品降本基本必达目标 | G41: 7月目标69.7万 实际达成148万 | H41: 1 | I41: 0.5 | J41: 0.5 | K41: 1.2 | L41: 1.2 | M41: 5400 | N41: 5000 | S41: 1 | T41: 1 | U41: 1000 | V41: 400 | W41: 5400
...

Sheet 云盘-原始（副本）
A1: 工号-新 | B1: 部门 | C1: 中心 | D1: 岗位 | E1: 姓名 | F1: 考核目标 | G1: 实际完成 | H1: 完成率 | I1: 权重 | J1: 目标得分 | K1: 总完成率 | L1: 总得分 | M1: 总奖金 | N1: 绩效基数 | O1: 奖金系数 | P1: 车补天数 | Q1: 车补 | R1: 备注 | S1: 排名 | T1: 排名系数 | U1: 奖金池总额 | V1: 奖金池绩效 | W1: 绩效奖金
A2: FD-071139 | B2: 线下渠道部 | D2: 督导 | E2: 王冬梅 | F2: 活动POS目标 500000 | G2: 1037582.8 | H2: 2.0751656 | I2: 0.35 | K2: 1.7077429 | L2: 1.5 | M2: 4050 | N2: 3000 | O2: 1.35 | P2: 24 | Q2: 384
B3: 线下渠道部 | D3: 督导 | F3: 个人pos目标 38000 | G3: 60521.51 | H3: 1.5926713 | I3: 0.35 | L3: 1.5
A4: FD-074553 | B4: 线下渠道部 | D4: 督导 | E4: 王娜 | F4: 活动POS目标 500000 | G4: 851012 | H4: 1.702024 | I4: 0.35 | K4: 1.5428642 | L4: 1.5 | M4: 3000 | N4: 3000 | O4: 1 | P4: 27 | Q4: 432
A5: FD-078246 | B5: 线下渠道部 | D5: 督导 | E5: 张婷 | F5: 活动POS目标 500000 | G5: 760591.4 | H5: 1.5211828 | I5: 0.35 | K5: 1.4778811 | L5: 1.5 | M5: 3000 | N5: 3000 | O5: 1 | P5: 27 | Q5: 432
A6: 外包督导 | B6: 线下渠道部 | D6: 督导 | E6: 时美娟 | F6: 活动POS目标 500000 | G6: 853560.43 | H6: 1.7071209 | I6: 0.35 | K6: 1.5809081 | L6: 1.5 | M6: 2400 | N6: 3000 | O6: 0.8
A7: FD-077555 | B7: 线下渠道部 | D7: 督导 | E7: 王琳 | F7: 活动POS目标 500000 | G7: 844581.7 | H7: 1.6891634 | I7: 0.35 | K7: 1.5296934 | L7: 1.5 | M7: 4050 | N7: 3000 | O7: 1.35 | P7: 29 | Q7: 464
A8: 外包督导 | B8: 线下渠道部 | D8: 督导 | E8: 刘茜 | F8: 活动POS目标 500000 | G8: 833877.42 | H8: 1.6677548 | I8: 0.35 | K8: 1.4989692 | L8: 1.5 | M8: 1500 | N8: 3000 | O8: 0.5
A9: FD-078109 | B9: 线下渠道部 | E9: 许元元 | Q9: 460
A10: FD-070643 | B10: 线下渠道部 | E10: 罗静文 | Q10: 500
A11: FD-078387 | B11: 线下渠道部 | E11: 李宏庆 | Q11: 420
A12: FD-076847 | B12: 线下渠道部 | E12: 蒋冰清 | Q12: 300
A13: FD-078748 | B13: 线下渠道部 | E13: 杨敏 | Q13: 500
A14: FD-070181 | B14: 线下渠道部 | E14: 梁倩雯 | Q14: 360
A15: FD-079435 | B15: 线下渠道部 | E15: 热夏提·古尔班江 | Q15: 460
A16: FD-070780 | B16: 线下渠道部 | E16: 黄策 | Q16: 380
A17: FD-074038 | B17: 线下渠道部 | E17: 黄慧琳 | Q17: 440
A18: FD-072418 | B18: 线下渠道部 | E18: 马诗瑾 | Q18: 340
A19: FD-076987 | B19: 线下渠道部 | E19: 孙海诺 | Q19: 340
A20: FD-075526 | B20: 线下渠道部 | E20: 夏星泽 | Q20: 576
... A22: FD-075978 | B22: 线下渠道部 | E22: 赵海宝 | Q22: 200
A23: FD-070915 | B23: 线下渠道部 | E23: 吴雪玲 | M23: 1800 | N23: 4000 | O23: 0.3 | R23: 当月绩效3600，5月6月绩效调整额-1800，计算后为1800
B24: 产品供应部 | D24: 主管 | E24: 李炜瑶 | F24: 货品降本基本必达目标 | G24: 7月目标69.7万 实际达成148万 | H24: 1 | I24: 0.5 | J24: 0.5 | K24: 1.2 | L24: 1.2 | M24: 5400 | N24: 5000 | S24: 1 | T24: 1 | U24: 1000 | V24: 400 | W24: 5400
B25: 产品供应部 | F25: 货品成本挑战目标 | G25: 7月目标13万 实际达成78 | H25: 1.5 | I25: 0.4 | J25: 0.6
B26: 产品供应部 | D26: 主管 | E26: 杨尚儒 | F26: 负评指标： WIS隐形水润面膜4.0：7.30前完成功效外检报告 赫系柔感洗发水2.0：7.31出货 KONO 控油奢护洗发水配方升级：7.20金标新设计打样完成 赫系赋活发膜3.0：7.30出货 | G26: 隐形水润4.0:7.22已完成外检功效报告 赫系柔感洗发水：7.25已出货 KONO控油奢护洗发水配方升级：由于设计确版逾期，7.27下推打样，预计8.10打样完成。 赫系赋活发膜3.0：7.20已出货。 | H26: 0.75 | I26: 0.1 | J26: 0.075 | K26: 1.013 | L26: 1.01 | M26: 5000 | N26: 5000 | S26: 6 | T26: 6 | U26: 1000 | W26: 5000
B27: 产品供应部 | E27: 陈林文 | F27: 计划准确率：83% | G27: 0.8355 | H27: 1 | I27: 0.2 | J27: 0.2 | K27: 1.0206 | L27: 1.02 | M27: 5100 | N27: 5000 | S27: 5 | T27: 5 | U27: 1000 | V27: 100 | W27: 5100
B28: 产品供应部 | E28: 朱丹萍 | F28: 降本项目目标达成率（目标37.7万） | G28: 98.68万（已确定） | H28: 1.4 | I28: 0.5 | J28: 0.7 | K28: 1.2 | L28: 1.2 | M28: 5400 | N28: 5000 | S28: 1 | T28: 1 | U28: 1000 | V28: 400 | W28: 5400
B29: 产品供应部 | E29: 郑烁纯 | F29: 供应商梯队优质率99% | G29: 7月份100% | H29: 1 | I29: 0.25 | J29: 0.25 | K29: 1.05 | L29: 1.05 | M29: 2100 | N29: 2000 | S29: 4 | T29: 4 | U29: 1000 | V29: 100 | W29: 2100
B30: 产品供应部 | E30: 吴永星 | F30: 物流降本挑战目标达成率指标 | G30: 目标：105.7万 结果：172.8万 | H30: 1.5 | I30: 0.4 | J30: 0.6 | K30: 1.187 | L30: 1.19 | M30: 5200 | N30: 5000 | S30: 2 | T30: 2 | U30: 1000 | V30: 200 | W30: 5200
B31: 产品供应部 | E31: 黄晓莲 | F31: 抖音体验分：可麦/IRY目标80分，其他品牌90分 | G31: 目标90分 实际92分 | H31: 1 | I31: 0.55 | J31: 0.55 | K31: 1.099 | L31: 1.1 | M31: 2200 | N31: 2000 | S31: 3 | T31: 3 | U31: 1000 | V31: 200 | W31: 2200
B32: 产品供应部 | E32: 谢昊 | F32: 降本指标：6.3万，实际达成：7.87w元，实际达成率125% | G32: 78781（已确定） | H32: 1.25 | I32: 0.4 | J32: 0.5 | K32: 1.1 | L32: 1.1 | M32: 5200 | N32: 5000 | S32: 3 | T32: 3 | U32: 1000 | V32: 200 | W32: 5200
B33: 产品供应部 | E33: 王誉炫 | F33: 包材订单履约率97% | G33: 0.987 | H33: 1 | I33: 0.35 | J33: 0.35 | K33: 0.8 | L33: 0.8 | M33: 4000 | N33: 4000 | S33: 7 | T33: 7 | U33: 1000 | W33: 4000
B34: 产品供应部 | E34: 陈远连 | F34: 降本目标20.9万 | G34: 23.6万 | H34: 1.13 | I34: 0.45 | J34: 0.50813397 | K34: 1.0581 | L34: 1.06 | M34: 2570.61 | N34: 0.51412298 | S34: 1 | T34: 1 | U34: 5000 | W34: 2570.61
B35: 产品供应部 | E35: 杨雄贤 | F35: 质量合格率 | G35: 1 | H35: 1 | I35: 0.45 | J35: 0.45 | K35: 1 | L35: 1 | M35: 2429.39 | N35: 0.48587702 | S35: 2 | T35: 2 | U35: 5000

Sheet 系统-原始
A1: 工号 | B1: 部门 | C1: 中心 | D1: 岗位 | E1: 姓名 | F1: 所属周期 | G1: 绩效方案名称 | H1: 任务名称 | I1: 任务内容 | J1: 目标 | K1: 实际完成数值 | L1: 完成情况说明 | M1: 单项完成率 | N1: 权重 | O1: 单项最终得分 | P1: 总完成率 | Q1: 总得分 | R1: 绩效奖金 | S1: 总奖金 | T1: 绩效基数 | U1: 子指标名称 | V1: 子指标说明 | W1: 子指标目标 | X1: 子指标完成量 | Y1: 子指标完成情况说明 | Z1: 子指标完成率 | AA1: 子指标权重 | AB1: 子指标得分
A2: FD-096937 | B2: 产品供应部-计划中心 | C2: 产品供应部-计划中心 | D2: 计划经理 | E2: 郭翠 | F2: 2026年07月 | G2: 产品供应部计划经理绩效考核方案 | H2: 生产履约目标完成率 | I2: 成品订单履约率完成95% | J2: 95 | K2: 0.971 | L2: 卓多姿35条目标，完成34条，1条未完成。34/35=97.1% | M2: 1.022 | N2: 0.5 | O2: 1 | P2: 0.911 | Q2: 0.91 | R2: 2821 | S2: 2821 | T2: 3100 | U2: 子指标名称 | V2: 子指标说明 | W2: 子指标目标 | X2: 子指标完成量 | Y2: 子指标完成情况说明 | Z2: 子指标完成率 | AA2: 子指标权重 | AB2: 子指标得分
A3: FD-096937 | B3: 产品供应部-计划中心 | C3: 产品供应部-计划中心 | D3: 计划经理 | E3: 郭翠 | F3: 2026年07月 | G3: 产品供应部计划经理绩效考核方案 | H3: 生产损耗 | I3: 损耗（按照中心降损目标比例完成） (损耗金额目标（除特殊高损耗订单外），其余订单损耗总金额≤在加工厂生产的总产值占所有加工厂生产总产值比重*15万元)） | K3: 1 | L3: 卓多姿目标损耗额39040元，卓多姿实际损耗额5617.1元 | M3: 1 | N3: 0.3 | O3: 1 | P3: 0.911 | Q3: 0.91 | R3: 2821 | S3: 2821 | T3: 3100 | U3: 子指标名称 | V3: 子指标说明 | W3: 子指标目标 | X3: 子指标完成量 | Y3: 子指标完成情况说明 | Z3: 子指标完成率 | AA3: 子指标权重 | AB3: 子指标得分
A4: FD-096937 | B4: 产品供应部-计划中心 | C4: 产品供应部-计划中心 | D4: 计划经理 | E4: 郭翠 | F4: 2026年07月 | G4: 产品供应部计划经理绩效考核方案 | H4: 部门关键项目完成率 | I4: 1、中心Skill项目推进 2、AI与计划中心文档 3、新品开发流程梳理，多维表格 | J4: 100 | K4: 0.5 | L4: 1、完成中心Skill项目推进（交流会、日常问题处理、Skill考核体系文档等）。2、完成AI与计划中心文档。3、完成新品开发流程多维表格。 | M4: 0.5 | N4: 0.2 | O4: 0.5 | P4: 0.911 | Q4: 0.91 | R4: 2821 | S4: 2821 | T4: 3100 | U4: 子指标名称 | V4: 子指标说明 | W4: 子指标目标 | X4: 子指标完成量 | Y4: 子指标完成情况说明 | Z4: 子指标完成率 | AA4: 子指标权重 | AB4: 子指标得分
A5: FD-098593 | B5: 产品供应部-计划中心 | C5: 产品供应部-计划中心 | D5: 计划经理 | E5: 王妙芳 | F5: 2026年07月 | G5: 产品供应部计划经理绩效考核方案 | H5: 计划准确率完成率 | I5: 准确率目标88% | J5: 0.88 | K5: 100%%%%% | L5: 准确率完成情况是88.91% | M5: 1 | N5: 0.3 | O5: 1 | P5: 0.95 | Q5: 0.95 | R5: 2968.9 | S5: 2968.9 | T5: 3000 | U5: 子指标名称 | V5: 子指标说明 | W5: 子指标目标 | X5: 子指标完成量 | Y5: 子指标完成情况说明 | Z5: 子指标完成率 | AA5: 子指标权重 | AB5: 子指标得分
A6: FD-098593 | B6: 产品供应部-计划中心 | C6: 产品供应部-计划中心 | D6: 计划经理 | E6: 王妙芳 | F6: 2026年07月 | G6: 产品供应部计划经理绩效考核方案 | H6: 总库存货值目标完成率 | I6: 总库存控制在179.5万内 | J6: 179.5万元 | K6: 167万元万元 | L6: 总库存控制在179.5万内 | M6: 1 | N6: 0.15 | O6: 1 | P6: 0.95 | Q6: 0.95 | R6: 2968.9 | S6: 2968.9 | T6: 3000 | U6: 子指标名称 | V6: 子指标说明 | W6: 子指标目标 | X6: 子指标完成量 | Y6: 子指标完成情况说明 | Z6: 子指标完成率 | AA6: 子指标权重 | AB6: 子指标得分
A7: FD-098593 | B7: 产品供应部-计划中心 | C7: 产品供应部-计划中心 | D7: 计划经理 | E7: 王妙芳 | F7: 2026年07月 | G7: 产品供应部计划经理绩效考核方案 | H7: 生产损耗 | I7: 按时准确提交 | K7: 100 | L7: 按时按量完成 | M7: 1 | N7: 0.05 | O7: 1 | P7: 0.95 | Q7: 0.95 | R7: 2968.9 | S7: 2968.9 | T7: 3000 | U7: 子指标名称 | V7: 子指标说明 | W7: 子指标目标 | X7: 子指标完成量 | Y7: 子指标完成情况说明 | Z7: 子指标完成率 | AA7: 子指标权重 | AB7: 子指标得分
A8: FD-098593 | B8: 产品供应部-计划中心 | C8: 产品供应部-计划中心 | D8: 计划经理 | E8: 王妙芳 | F8: 2026年07月 | G8: 产品供应部计划经理绩效考核方案 | H8: 部门关键项目完成率 | I8: 1、月度报废 2、IRY下单量协商 3、库存管理范围与方法课件输出 4、IRY赠品降本方案输出与沟通 | J8: 1 | K8: 88%% | L8: 1、月度报废--已完成，已输出报废文件 2、IRY下单量协商--已完成，已确认好下单需求数量 3、库存管理范围与方法课件输出--输出后驳回，重新补充内容 4、IRY赠品降本方案输出与沟通--已完成输出，品牌需求变更 | M8: 0.9 | N8: 0.5 | O8: 0.9 | P8: 0.95 | Q8: 0.95 | R8: 2968.9 | S8: 2968.9 | T8: 3000 | U8: 子指标名称 | V8: 子指标说明 | W8: 子指标目标 | X8: 子指标完成量 | Y8: 子指标完成情况说明 | Z8: 子指标完成率 | AA8: 子指标权重 | AB8: 子指标得分
A9: FD-091691 | B9: 产品供应部-计划中心 | C9: 产品供应部-计划中心 | D9: 计划经理 | E9: 吴开智 | F9: 2026年07月 | G9: 产品供应部计划经理绩效考核方案 | H9: 总库存货值目标完成率 | I9: 1750 | J9: 1750万 | K9: 1548万万万 | M9: 1.13 | N9: 0.3 | O9: 1.13 | P9: 1.0025 | Q9: 0.85 | R9: 2550 | S9: 2550 | T9: 3000 | U9: 子指标名称 | V9: 子指标说明 | W9: 子指标目标 | X9: 子指标完成量 | Y9: 子指标完成情况说明 | Z9: 子指标完成率 | AA9: 子指标权重 | AB9: 子指标得分
A10: FD-091691 | B10: 产品供应部-计划中心 | C10: 产品供应部-计划中心 | D10: 计划经理 | E10: 吴开智 | F10: 2026年07月 | G10: 产品供应部计划经理绩效考核方案 | H10: 部门关键项目完成率 | I10: 眼膜测试 | J10: 100 | K10: 0.95 | M10: 0.95 | N10: 0.4 | O10: 0.95 | P10: 1.0025 | Q10: 0.85 | R10: 2550 | S10: 2550 | T10: 3000 | U10: 子指标名称 | V10: 子指标说明 | W10: 子指标目标 | X10: 子指标完成量 | Y10: 子指标完成情况说明 | Z10: 子指标完成率 | AA10: 子指标权重 | AB10: 子指标得分
A11: FD-091691 | B11: 产品供应部-计划中心 | C11: 产品供应部-计划中心 | D11: 计划经理 | E11: 吴开智 | F11: 2026年07月 | G11: 产品供应部计划经理绩效考核方案 | H11: 计划准确率完成率 | I11: 计划准确率81% | J11: 81 | K11: 76.53 | M11: 0.945 | N11: 0.3 | O11: 0.95 | P11: 1.0025 | Q11: 0.85 | R11: 2550 | S11: 2550 | T11: 3000 | U11: 子指标名称 | V11: 子指标说明 | W11: 子指标目标 | X11: 子指标完成量 | Y11: 子指标完成情况说明 | Z11: 子指标完成率 | AA11: 子指标权重 | AB11: 子指标得分
A12: FD-085087 | B12: 产品供应部-计划中心 | C12: 产品供应部-计划中心 | D12: 计划经理 | E12: 张璐萍 | F12: 2026年07月 | G12: 产品供应部计划经理绩效考核方案 | H12: 部门关键项目完成率 | I12: 1、损耗率降低至1.5%以下-损耗分析输出。寻找降损点 2、KONO经典系列限定款去膜 -说服品牌方去膜 3、凡岛工厂与总部流程优化与执行-1. 第二模块的详细流程 4、加工厂基础跟产流程各类定义、解释和对应端口梳理（跟产名词、细节宝典）-完善第二板块，写第三板块 5、8g袋包降损-1. 推进袋包机购置方案 6、料体高损耗降损-1. 软管打样上级，测试损耗率 7、凡岛临期原料管理-1. 与工厂了解临期原料管理流程 2. 与供应端梳理新流程情况 3. 结合新流程重新共识 | J12: 1 | K12: 92%%% | L12: 1、损耗率降低至1.5%以下-损耗分析输出。寻找降损点（已完成） 2、KONO经典系列限定款去膜 -说服品牌方去膜 （已完成，项目暂停）3、凡岛工厂与总部流程优化与执行-1. 第二模块的详细流程 （已完成）4、加工厂基础跟产流程各类定义、解释和对应端口梳理（跟产名词、细节宝典）-完善第二板块，写第三板块 （已完成）5、8g袋包降损-1. 推进袋包机购置方案 （不推进购置，确认其他方案90%））6、料体高损耗降损-1. 软管打样上级，测试损耗率 （待测试结果，完成95%）7、凡岛临期原料管理-1. 与工厂了解临期原料管理流程 2. 与供应端梳理新流程情况 3. 结合新流程重新共识（待试运行，完成90%） | M12: 0.92 | N12: 0.2 | O12: 0.92 | P12: 0.9396 | Q12: 0.99 | R12: 3475.6 | S12: 3475.6 | T12: 3000 | U12: 子指标名称 | V12: 子指标说明 | W12: 子指标目标 | X12: 子指标完成量 | Y12: 子指标完成情况说明 | Z12: 子指标完成率 | AA12: 子指标权重 | AB12: 子指标得分
A13: FD-085087 | B13: 产品供应部-计划中心 | C13: 产品供应部-计划中心 | D13: 计划经理 | E13: 张璐萍 | F13: 2026年07月 | G13: 产品供应部计划经理绩效考核方案 | H13: 生产履约目标完成率 | I13: 凡岛工厂履约95% | J13: 0.95 | K13: 0.962 | L13: 7月目标共106条，，履约102条，未履约4条 工厂原因：均为乳化锅损坏导致乳化延后 【WIS乳糖酸多效面膜2.0_25g×10片】 【赫系轻盈洗发水3.0 450g】 【赫系水光护发素新配方450ml（短泵头）】 其中洗发水和护发素虽然减少计划因此生产数量达标，但是因设备问题较为严重，最后一条目标我没有算履约，由此提高对设备维护的重视 非工厂原因： 【WIS焕颜透嫩紧致淡纹精华液30ml】 原料逾期 | M13: 1 | N13: 0.5 | O13: 1 | P13: 0.9396 | Q13: 0.99 | R13: 3475.6 | S13: 3475.6 | T13: 3000 | U13: 子指标名称 | V13: 子指标说明 | W13: 子指标目标 | X13: 子指标完成量 | Y13: 子指标完成情况说明 | Z13: 子指标完成率 | AA13: 子指标权重 | AB13: 子指标得分
A14: FD-085087 | B14: 产品供应部-计划中心 | C14: 产品供应部-计划中心 | D14: 计划经理 | E14: 张璐萍 | F14: 2026年07月 | G14: 产品供应部计划经理绩效考核方案 | H14: 生产损耗 | I14: 负责加工厂损耗总金额/负责加工厂产值占本月排产生产的比重≤10万元 | K14: 6.14万元 | L14: 7月目标共106条，，履约102条，未履约4条 工厂原因：均为乳化锅损坏导致乳化延后 【WIS乳糖酸多效面膜2.0_25g×10片】 【赫系轻盈洗发水3.0 450g】 【赫系水光护发素新配方450ml（短泵头）】 其中洗发水和护发素虽然减少计划因此生产数量达标，但是因设备问题较为严重，最后一条目标我没有算履约，由此提高对设备维护的重视 非工厂原因： 【WIS焕颜透嫩紧致淡纹精华液30ml】 原料逾期 | M14: 0.852 | N14: 0.3 | O14: 0.852 | P14: 0.9396 | Q14: 0.99 | R14: 3475.6 | S14: 3475.6 | T14: 3000 | U14: 子指标名称 | V14: 子指标说明 | W14: 子指标目标 | X14: 子指标完成量 | Y14: 子指标完成情况说明 | Z14: 子指标完成率 | AA14: 子指标权重 | AB14: 子指标得分
A15: FD-094730 | B15: 产品供应部-计划中心 | C15: 产品供应部-计划中心 | D15: 计划经理 | E15: 魏振涛 | F15: 2026年07月 | G15: 产品供应部计划经理绩效考核方案 | H15: 部门关键项目完成率 | I15: 1、TCO落地计算 2、找到1-1.5、1.5-2以及物料稳定出库方案 | J15: 2条 | K15: 95%条 | L15: TCO完成，效期出库只有物料还无出库方案，新增返工费用计算完成 | M15: 0.95 | N15: 0.4 | O15: 0.95 | P15: 0.905 | Q15: 0.91 | R15: 2730 | S15: 2730 | T15: 3000 | U15: 子指标名称 | V15: 子指标说明 | W15: 子指标目标 | X15: 子指标完成量 | Y15: 子指标完成情况说明 | Z15: 子指标完成率 | AA15: 子指标权重 | AB15: 子指标得分
A16: FD-094730 | B16: 产品供应部-计划中心 | C16: 产品供应部-计划中心 | D16: 计划经理 | E16: 魏振涛 | F16: 2026年07月 | G16: 产品供应部计划经理绩效考核方案 | H16: 总库存货值目标完成率 | I16: 库存水位 | J16: 851万 | K16: 960万 | L16: 30号当天库存960万，完成率89% | M16: 0.89 | N16: 0.3 | O16: 0.89 | P16: 0.905 | Q16: 0.91 | R16: 2730 | S16: 2730 | T16: 3000 | U16: 子指标名称 | V16: 子指标说明 | W16: 子指标目标 | X16: 子指标完成量 | Y16: 子指标完成情况说明 | Z16: 子指标完成率 | AA16: 子指标权重 | AB16: 子指标得分
A17: FD-094730 | B17: 产品供应部-计划中心 | C17: 产品供应部-计划中心 | D17: 计划经理 | E17: 魏振涛 | F17: 2026年07月 | G17: 产品供应部计划经理绩效考核方案 | H17: 计划准确率完成率 | I17: 预测准确率82% | J17: 0.82 | K17: 0.705 | L17: 准确率70.5，换算完成率85% | M17: 0.86 | N17: 0.3 | O17: 0.86 | P17: 0.905 | Q17: 0.91 | R17: 2730 | S17: 2730 | T17: 3000 | U17: 子指标名称 | V17: 子指标说明 | W17: 子指标目标 | X17: 子指标完成量 | Y17: 子指标完成情况说明 | Z17: 子指标完成率 | AA17: 子指标权重 | AB17: 子指标得分
A18: FD-177153 | B18: 产品供应部-计划中心 | C18: 产品供应部-计划中心 | D18: 计划经理 | E18: 马猷安 | F18: 2026年07月 | G18: 产品供应部计划经理绩效考核方案 | H18: 部门关键项目完成率 | I18: 1. 数据上金蝶 2. 加工厂库位管理 3. 生产端包材优化 4. 杜明、郭翠带教 | J18: 1 | K18: 85%% | L18: 包材成本优化板块 没有深入学习和拓展 | M18: 0.85 | N18: 0.6 | O18: 0.85 | P18: 0.972 | Q18: 0.98 | R18: 3058.9 | S18: 3058.9 | T18: 3000 | U18: 子指标名称 | V18: 子指标说明 | W18: 子指标目标 | X18: 子指标完成量 | Y18: 子指标完成情况说明 | Z18: 子指标完成率 | AA18: 子指标权重 | AB18: 子指标得分
A19: FD-177153 | B19: 产品供应部-计划中心 | C19: 产品供应部-计划中心 | D19: 计划经理 | E19: 马猷安 | F19: 2026年07月 | G19: 产品供应部计划经理绩效考核方案 | H19: 生产损耗 | I19: 梦莎、美汇做货 | K19: 2119 | L19: 总目标金额5720， 实际损耗金额2119 | M19: 1.62 | N19: 0.1 | O19: 1.5 | P19: 0.972 | Q19: 0.98 | R19: 3058.9 | S19: 3058.9 | T19: 3000 | U19: 子指标名称 | V19: 子指标说明 | W19: 子指标目标 | X19: 子指标完成量 | Y19: 子指标完成情况说明 | Z19: 子指标完成率 | AA19: 子指标权重 | AB19: 子指标得分
A20: FD-177153 | B20: 产品供应部-计划中心 | C20: 产品供应部-计划中心 | D20: 计划经理 | E20: 马猷安 | F20: 2026年07月 | G20: 产品供应部计划经理绩效考核方案 | H20: 生产履约目标完成率 | I20: 梦莎、美汇做货 | J20: 1 | K20: 1 | L20: 总目标金额5720， 实际损耗金额2119 | M20: 1 | N20: 0.3 | O20: 1 | P20: 0.972 | Q20: 0.98 | R20: 3058.9 | S20: 3058.9 | T20: 3000 | U20: 子指标名称 | V20: 子指标说明 | W20: 子指标目标 | X20: 子指标完成量 | Y20: 子指标完成情况说明 | Z20: 子指标完成率 | AA20: 子指标权重 | AB20: 子指标得分
A21: FD-097678 | B21: 产品供应部-计划中心 | C21: 产品供应部-计划中心 | D21: 管培生 | E21: 钟恩宝 | F21: 2026年07月 | G21: 产品供应部计划经理绩效考核方案 | H21: 部门关键项目完成率 | I21: 关键项目 | J21: 1 | K21: 90%%% | L21: 总目标金额5720， 实际损耗金额2119 | M21: 0.9 | N21: 0.4 | O21: 0.9 | P21: 1.00971 | Q21: 1.01 | R21: 5525.6 | S21: 5525.6 | T21: 5000 | U21: 子指标名称 | V21: 子指标说明 | W21: 子指标目标 | X21: 子指标完成量 | Y21: 子指标完成情况说明 | Z21: 子指标完成率 | AA21: 子指标权重 | AB21: 子指标得分
A22: FD-097678 | B22: 产品供应部-计划中心 | C22: 产品供应部-计划中心 | D22: 管培生 | E22: 钟恩宝 | F22: 2026年07月 | G22: 产品供应部计划经理绩效考核方案 | H22: 计划准确率完成率 | I22: 预测准确率 | J22: 0.9 | K22: 90.33%% | L22: 总目标金额5720， 实际损耗金额2119 | M22: 1.0037 | N22: 0.3 | O22: 1 | P22: 1.00971 | Q22: 1.01 | R22: 5525.6 | S22: 5525.6 | T22: 5000 | U22: 子指标名称 | V22: 子指标说明 | W22: 子指标目标 | X22: 子指标完成量 | Y22: 子指标完成情况说明 | Z22: 子指标完成率 | AA22: 子指标权重 | AB22: 子指标得分
A23: FD-097678 | B23: 产品供应部-计划中心 | C23: 产品供应部-计划中心 | D23: 管培生 | E23: 钟恩宝 | F23: 2026年07月 | G23: 产品供应部计划经理绩效考核方案 | H23: 总库存货值目标完成率 | I23: 目标1150w | J23: 1150万元 | K23: 964万元万元万元 | L23: 总目标金额5720， 实际损耗金额2119 | M23: 1.162 | N23: 0.3 | O23: 1.162 | P23: 1.00971 | Q23: 1.01 | R23: 5525.6 | S23: 5525.6 | T23: 5000 | U23: 子指标名称 | V23: 子指标说明 | W23: 子指标目标 | X23: 子指标完成量 | Y23: 子指标完成情况说明 | Z23: 子指标完成率 | AA23: 子指标权重 | AB23: 子指标得分
A24: FD-092488 | B24: 产品供应部-计划中心 | C24: 产品供应部-计划中心 | D24: 管培生 | E24: 林杜明 | F24: 2026年07月 | G24: 产品供应部计划经理绩效考核方案 | H24: 生产履约目标完成率 | I24: 沪汇加工厂履约率 | J24: 1 | K24: 1 | L24: 沪汇7月份履约率100% | M24: 1 | N24: 0.3 | O24: 1 | P24: 0.89 | Q24: 0.91 | R24: 0 | S24: 0 | T24: 5000 | U24: 子指标名称 | V24: 子指标说明 | W24: 子指标目标 | X24: 子指标完成量 | Y24: 子指标完成情况说明 | Z24: 子指标完成率 | AA24: 子指标权重 | AB24: 子指标得分
A25: FD-092488 | B25: 产品供应部-计划中心 | C25: 产品供应部-计划中心 | D25: 管培生 | E25: 林杜明 | F25: 2026年07月 | G25: 产品供应部计划经理绩效考核方案 | H25: 生产损耗 | I25: 沪汇加工厂损耗率 | K25: 0.5 | L25: 沪汇7月份履约率100% | M25: 0.3 | N25: 0.1 | O25: 0.5 | P25: 0.89 | Q25: 0.91 | R25: 0 | S25: 0 | T25: 5000 | U25: 子指标名称 | V25: 子指标说明 | W25: 子指标目标 | X25: 子指标完成量 | Y25: 子指标完成情况说明 | Z25: 子指标完成率 | AA25: 子指标权重 | AB25: 子指标得分
A26: FD-092488 | B26: 产品供应部-计划中心 | C26: 产品供应部-计划中心 | D26: 管培生 | E26: 林杜明 | F26: 2026年07月 | G26: 产品供应部计划经理绩效考核方案 | H26: 部门关键项目完成率 | I26: 全链路成本计算 | J26: 1 | K26: 0.9 | L26: 沪汇7月份履约率100% | M26: 0.9 | N26: 0.2 | O26: 0.9 | P26: 0.89 | Q26: 0.91 | R26: 0 | S26: 0 | T26: 5000 | U26: 子指标名称 | V26: 子指标说明 | W26: 子指标目标 | X26: 子指标完成量 | Y26: 子指标完成情况说明 | Z26: 子指标完成率 | AA26: 子指标权重 | AB26: 子指标得分
A27: FD-092488 | B27: 产品供应部-计划中心 | C27: 产品供应部-计划中心 | D27: 管培生 | E27: 林杜明 | F27: 2026年07月 | G27: 产品供应部计划经理绩效考核方案 | H27: 部门关键项目完成率 | I27: 凡岛工厂排产优化 | J27: 1 | K27: 0.9 | L27: 沪汇7月份履约率100% | M27: 0.9 | N27: 0.2 | O27: 0.9 | P27: 0.89 | Q27: 0.91 | R27: 0 | S27: 0 | T27: 5000 | U27: 子指标名称 | V27: 子指标说明 | W27: 子指标目标 | X27: 子指标完成量 | Y27: 子指标完成情况说明 | Z27: 子指标完成率 | AA27: 子指标权重 | AB27: 子指标得分
A28: FD-092488 | B28: 产品供应部-计划中心 | C28: 产品供应部-计划中心 | D28: 管培生 | E28: 林杜明 | F28: 2026年07月 | G28: 产品供应部计划经理绩效考核方案 | H28: 部门关键项目完成率 | I28: workbuddy课程培训 | J28: 1 | K28: 1 | M28: 1 | N28: 0.2 | O28: 1 | P28: 0.89 | Q28: 0.91 | R28: 0 | S28: 0 | T28: 5000 | U28: 子指标名称 | V28: 子指标说明 | W28: 子指标目标 | X28: 子指标完成量 | Y28: 子指标完成情况说明 | Z28: 子指标完成率 | AA28: 子指标权重 | AB28: 子指标得分
A29: OD-002451 | B29: 人资行政部-组织发展中心 | C29: 人资行政部-组织发展中心 | D29: SSC助理 | E29: 陆颖 | F29: 2026年07月 | G29: 人资行政部-组织发展中心-SSC助理 | H29: 例行工作及时率 | I29: 按照对应节点完成各项工作 | J29: 1 | K29: 0 | L29: 已按照节点完成 | M29: 1 | N29: 0.5 | O29: 1 | P29: 1 | Q29: 1 | R29: 1500 | S29: 1500 | T29: 1500 | U29: 转正管理及时率 | V29: 6.30完成7、8月转正名单更新；7.10完成6月转正考勤更新；7.29完成6月转正结果更新；7.30完成8、9月转正名单更新 | X29: 子指标完成量 | Y29: 6.30更新7、8月预计转正名单，7.9更新转正考勤，7.29更新转正结果，7.30更新8、9月转正名单 | Z29: 1 | AA29: 0.2 | AB29: 1
A30: OD-002451 | B30: 人资行政部-组织发展中心 | C30: 人资行政部-组织发展中心 | D30: SSC助理 | E30: 陆颖 | F30: 2026年07月 | G30: 人资行政部-组织发展中心-SSC助理 | H30: 例行工作及时率 | I30: 按照对应节点完成各项工作 | J30: 1 | K30: 0 | L30: 已按照节点完成 | M30: 1 | N30: 0.5 | O30: 1 | P30: 1 | Q30: 1 | R30: 1500 | S30: 1500 | T30: 1500 | U30: 月度考勤报表提交及时率 | V30: 7月6号前完成6月月度考勤表（初版） | X30: 子指标完成量 | Y30: 7.6完成6月月度考勤表 | Z30: 1 | AA30: 0.4 | AB30: 1
A31: OD-002451 | B31: 人资行政部-组织发展中心 | C31: 人资行政部-组织发展中心 | D31: SSC助理 | E31: 陆颖 | F31: 2026年07月 | G31: 人资行政部-组织发展中心-SSC助理 | H31: 例行工作及时率 | I31: 按照对应节点完成各项工作 | J31: 1 | K31: 0 | L31: 已按照节点完成 | M31: 1 | N31: 0.5 | O31: 1 | P31: 1 | Q31: 1 | R31: 1500 | S31: 1500 | T31: 1500 | U31: 三方处理及时率 | V31: 1-3个工作日内，完成三方发起 | X31: 子指标完成量 | Y31: 7月处理两方/三方需求合计3人，已结束2人，流程中1人（等同学补充资料） | Z31: 1 | AA31: 0.2 | AB31: 1
A32: OD-002451 | B32: 人资行政部-组织发展中心 | C32: 人资行政部-组织发展中心 | D32: SSC助理 | E32: 陆颖 | F32: 2026年07月 | G32: 人资行政部-组织发展中心-SSC助理 | H32: 例行工作及时率 | I32: 按照对应节点完成各项工作 | J32: 1 | K32: 0 | L32: 已按照节点完成 | M32: 1 | N32: 0.5 | O32: 1 | P32: 1 | Q32: 1 | R32: 1500 | S32: 1500 | T32: 1500 | U32: 竞业处理及时率 | V32: 7.7完成7月竞业打款名单；7.25前完成7月竞业跟进总结 | X32: 子指标完成量 | Y32: 7.7确认7月竞业打款名单，7.24完成竞业跟进总结 | Z32: 1 | AA32: 0.1 | AB32: 1
A33: OD-002451 | B33: 人资行政部-组织发展中心 | C33: 人资行政部-组织发展中心 | D33: SSC助理 | E33: 陆颖 | F33: 2026年07月 | G33: 人资行政部-组织发展中心-SSC助理 | H33: 例行工作及时率 | I33: 按照对应节点完成各项工作 | J33: 1 | K33: 0 | L33: 已按照节点完成 | M33: 1 | N33: 0.5 | O33: 1 | P33: 1 | Q33: 1 | R33: 1500 | S33: 1500 | T33: 1500 | U33: 调动处理及时率 | V33: 1-2个工作日内，完成组织架构/岗位/负责人/HR经理维护更新 | X33: 子指标完成量 | Y33: 已按照节点完成 | Z33: 1 | AA33: 0.1 | AB33: 1
A34: OD-002451 | B34: 人资行政部-组织发展中心 | C34: 人资行政部-组织发展中心 | D34: SSC助理 | E34: 陆颖 | F34: 2026年07月 | G34: 人资行政部-组织发展中心-SSC助理 | H34: 例行工作准确率 | I34: 保证各项工作准确无误 | J34: 1 | K34: 0 | L34: 准确完成 | M34: 1 | N34: 0.5 | O34: 1 | P34: 1 | Q34: 1 | R34: 1500 | S34: 1500 | T34: 1500 | U34: 转正名单及结果更新准确率 | V34: 确保转正名单、考勤、结果准确 | X34: 准确完成 | Y34: 已按照节点完成 | Z34: 1 | AA34: 0.2 | AB34: 1
A35: OD-002451 | B35: 人资行政部-组织发展中心 | C35: 人资行政部-组织发展中心 | D35: SSC助理 | E35: 陆颖 | F35: 2026年07月 | G35: 人资行政部-组织发展中心-SSC助理 | H35: 例行工作准确率 | I35: 保证各项工作准确无误 | J35: 1 | K35: 0 | L35: 准确完成 | M35: 1 | N35: 0.5 | O35: 1 | P35: 1 | Q35: 1 | R35: 1500 | S35: 1500 | T35: 1500 | U35: 月度考勤报表准确率 | V35: 确保月度考勤表准确 | X35: 准确完成 | Y35: 已按照节点完成 | Z35: 1 | AA35: 0.4 | AB35: 1
A36: OD-002451 | B36: 人资行政部-组织发展中心 | C36: 人资行政部-组织发展中心 | D36: SSC助理 | E36: 陆颖 | F36: 2026年07月 | G36: 人资行政部-组织发展中心-SSC助理 | H36: 例行工作准确率 | I36: 保证各项工作准确无误 | J36: 1 | K36: 0 | L36: 准确完成 | M36: 1 | N36: 0.5 | O36: 1 | P36: 1 | Q36: 1 | R36: 1500 | S36: 1500 | T36: 1500 | U36: 三方处理准确率 | V36: 确保薪资、协议内容、时间等准确 | X36: 准确完成 | Y36: 已按照节点完成 | Z36: 1 | AA36: 0.2 | AB36: 1
A37: OD-002451 | B37: 人资行政部-组织发展中心 | C37: 人资行政部-组织发展中心 | D37: SSC助理 | E37: 陆颖 | F37: 2026年07月 | G37: 人资行政部-组织发展中心-SSC助理 | H37: 例行工作准确率 | I37: 保证各项工作准确无误 | J37: 1 | K37: 0 | L37: 准确完成 | M37: 1 | N37: 0.5 | O37: 1 | P37: 1 | Q37: 1 | R37: 1500 | S37: 1500 | T37: 1500 | U37: 竞业处理准确率 | V37: 确保竞业金额、名单、生效周期准确 | X37: 准确完成 | Y37: 已按照节点完成 | Z37: 1 | AA37: 0.1 | AB37: 1
A38: OD-002451 | B38: 人资行政部-组织发展中心 | C38: 人资行政部-组织发展中心 | D38: SSC助理 | E38: 陆颖 | F38: 2026年07月 | G38: 人资行政部-组织发展中心-SSC助理 | H38: 例行工作准确率 | I38: 保证各项工作准确无误 | J38: 1 | K38: 0 | L38: 准确完成 | M38: 1 | N38: 0.5 | O38: 1 | P38: 1 | Q38: 1 | R38: 1500 | S38: 1500 | T38: 1500 | U38: 工时更新准确率 | V38: 确认工时数据准确 | X38: 准确完成 | Y38: 已按照节点完成 | Z38: 1 | AA38: 0.1 | AB38: 1
A39: OD-000664 | B39: 人资行政部-组织发展中心 | C39: 人资行政部-组织发展中心 | D39: SSC助理 | E39: 宋月 | F39: 2026年07月 | G39: 人资行政部-组织发展中心-SSC助理 | H39: 例行工作及时率 | I39: 季度评级：跟进OA岛民上级提交 定计划文档提交率80% 7.13完成绩效数据整理 | J39: 1 | K39: 0 | L39: 季度评级：跟进OA岛民上级提交 定计划文档提交率80% 7.13完成绩效数据整理 7.10完成 | M39: 1.075 | N39: 0.5 | O39: 1.075 | P39: 1.0285 | Q39: 1.03 | R39: 2060 | S39: 2060 | T39: 2000 | U39: 绩效数据汇总分析完成率 | X39: 准确完成 | Y39: 7.10完成 | Z39: 1.2 | AA39: 0.6 | AB39: 1.2
A40: OD-000664 | B40: 人资行政部-组织发展中心 | C40: 人资行政部-组织发展中心 | D40: SSC助理 | E40: 宋月 | F40: 2026年07月 | G40: 人资行政部-组织发展中心-SSC助理 | H40: 例行工作及时率 | I40: 季度评级：跟进OA岛民上级提交 定计划文档提交率80% 7.13完成绩效数据整理 | J40: 1 | K40: 0 | L40: 季度评级：跟进OA岛民上级提交 定计划文档提交率80% 7.13完成绩效数据整理 7.10完成 | M40: 1.075 | N40: 0.5 | O40: 1.075 | P40: 1.0285 | Q40: 1.03 | R40: 2060 | S40: 2060 | T40: 2000 | U40: 定计划审批提交率80% | X40: 准确完成 | Y40: 提交73% | Z40: 0.73 | AA40: 0.1 | AB40: 0.73
...

Sheet 系统-原始（副本）
A1: 工号 | B1: 部门 | C1: 中心 | D1: 岗位 | E1: 姓名 | F1: 所属周期 | G1: 绩效方案名称 | H1: 任务名称 | I1: 任务内容 | J1: 目标 | K1: 实际完成数值 | L1: 完成情况说明 | M1: 单项完成率 | N1: 权重 | O1: 单项最终得分 | P1: 总完成率 | Q1: 总得分 | R1: 绩效奖金 | S1: 总奖金 | T1: 绩效基数 | U1: 子指标名称 | V1: 子指标说明 | W1: 子指标目标 | X1: 子指标完成量 | Y1: 子指标完成情况说明 | Z1: 子指标完成率 | AA1: 子指标权重 | AB1: 子指标得分
A2: FD-096937 | B2: 产品供应部-计划中心 | C2: 产品供应部-计划中心 | D2: 计划经理 | E2: 郭翠 | F2: 2026年07月 | G2: 产品供应部计划经理绩效考核方案 | H2: 生产履约目标完成率 | I2: 成品订单履约率完成95% | J2: 95 | K2: 0.971 | L2: 卓多姿35条目标，完成34条，1条未完成。34/35=97.1% | M2: 1.022 | N2: 0.5 | O2: 1 | P2: 0.911 | Q2: 0.91 | R2: 2821 | S2: 2821 | T2: 3100 | U2: 子指标名称 | V2: 子指标说明 | W2: 子指标目标 | X2: 子指标完成量 | Y2: 子指标完成情况说明 | Z2: 子指标完成率 | AA2: 子指标权重 | AB2: 子指标得分
A3: FD-098593 | B3: 产品供应部-计划中心 | C3: 产品供应部-计划中心 | D3: 计划经理 | E3: 王妙芳 | F3: 2026年07月 | G3: 产品供应部计划经理绩效考核方案 | H3: 计划准确率完成率 | I3: 准确率目标88% | J3: 0.88 | K3: 100%%%%% | L3: 准确率完成情况是88.91% | M3: 1 | N3: 0.3 | O3: 1 | P3: 0.95 | Q3: 0.95 | R3: 2968.9 | S3: 2968.9 | T3: 3000 | U3: 子指标名称 | V3: 子指标说明 | W3: 子指标目标 | X3: 子指标完成量 | Y3: 子指标完成情况说明 | Z3: 子指标完成率 | AA3: 子指标权重 | AB3: 子指标得分
A4: FD-091691 | B4: 产品供应部-计划中心 | C4: 产品供应部-计划中心 | D4: 计划经理 | E4: 吴开智 | F4: 2026年07月 | G4: 产品供应部计划经理绩效考核方案 | H4: 总库存货值目标完成率 | I4: 1750 | J4: 1750万 | K4: 1548万万万 | M4: 1.13 | N4: 0.3 | O4: 1.13 | P4: 1.0025 | Q4: 0.85 | R4: 2550 | S4: 2550 | T4: 3000 | U4: 子指标名称 | V4: 子指标说明 | W4: 子指标目标 | X4: 子指标完成量 | Y4: 子指标完成情况说明 | Z4: 子指标完成率 | AA4: 子指标权重 | AB4: 子指标得分
A5: FD-085087 | B5: 产品供应部-计划中心 | C5: 产品供应部-计划中心 | D5: 计划经理 | E5: 张璐萍 | F5: 2026年07月 | G5: 产品供应部计划经理绩效考核方案 | H5: 部门关键项目完成率 | I5: 1、损耗率降低至1.5%以下-损耗分析输出。寻找降损点 2、KONO经典系列限定款去膜 -说服品牌方去膜 3、凡岛工厂与总部流程优化与执行-1. 第二模块的详细流程 4、加工厂基础跟产流程各类定义、解释和对应端口梳理（跟产名词、细节宝典）-完善第二板块，写第三板块 5、8g袋包降损-1. 推进袋包机购置方案 6、料体高损耗降损-1. 软管打样上级，测试损耗率 7、凡岛临期原料管理-1. 与工厂了解临期原料管理流程 2. 与供应端梳理新流程情况 3. 结合新流程重新共识 | J5: 1 | K5: 92%%% | L5: 1、损耗率降低至1.5%以下-损耗分析输出。寻找降损点（已完成） 2、KONO经典系列限定款去膜 -说服品牌方去膜 （已完成，项目暂停）3、凡岛工厂与总部流程优化与执行-1. 第二模块的详细流程 （已完成）4、加工厂基础跟产流程各类定义、解释和对应端口梳理（跟产名词、细节宝典）-完善第二板块，写第三板块 （已完成）5、8g袋包降损-1. 推进袋包机购置方案 （不推进购置，确认其他方案90%））6、料体高损耗降损-1. 软管打样上级，测试损耗率 （待测试结果，完成95%）7、凡岛临期原料管理-1. 与工厂了解临期原料管理流程 2. 与供应端梳理新流程情况 3. 结合新流程重新共识（待试运行，完成90%） | M5: 0.92 | N5: 0.2 | O5: 0.92 | P5: 0.9396 | Q5: 0.99 | R5: 3475.6 | S5: 3475.6 | T5: 3000 | U5: 子指标名称 | V5: 子指标说明 | W5: 子指标目标 | X5: 子指标完成量 | Y5: 子指标完成情况说明 | Z5: 子指标完成率 | AA5: 子指标权重 | AB5: 子指标得分
A6: FD-094730 | B6: 产品供应部-计划中心 | C6: 产品供应部-计划中心 | D6: 计划经理 | E6: 魏振涛 | F6: 2026年07月 | G6: 产品供应部计划经理绩效考核方案 | H6: 部门关键项目完成率 | I6: 1、TCO落地计算 2、找到1-1.5、1.5-2以及物料稳定出库方案 | J6: 2条 | K6: 95%条 | L6: TCO完成，效期出库只有物料还无出库方案，新增返工费用计算完成 | M6: 0.95 | N6: 0.4 | O6: 0.95 | P6: 0.905 | Q6: 0.91 | R6: 2730 | S6: 2730 | T6: 3000 | U6: 子指标名称 | V6: 子指标说明 | W6: 子指标目标 | X6: 子指标完成量 | Y6: 子指标完成情况说明 | Z6: 子指标完成率 | AA6: 子指标权重 | AB6: 子指标得分
A7: FD-177153 | B7: 产品供应部-计划中心 | C7: 产品供应部-计划中心 | D7: 计划经理 | E7: 马猷安 | F7: 2026年07月 | G7: 产品供应部计划经理绩效考核方案 | H7: 部门关键项目完成率 | I7: 1. 数据上金蝶 2. 加工厂库位管理 3. 生产端包材优化 4. 杜明、郭翠带教 | J7: 1 | K7: 85%% | L7: 包材成本优化板块 没有深入学习和拓展 | M7: 0.85 | N7: 0.6 | O7: 0.85 | P7: 0.972 | Q7: 0.98 | R7: 3058.9 | S7: 3058.9 | T7: 3000 | U7: 子指标名称 | V7: 子指标说明 | W7: 子指标目标 | X7: 子指标完成量 | Y7: 子指标完成情况说明 | Z7: 子指标完成率 | AA7: 子指标权重 | AB7: 子指标得分
A8: FD-097678 | B8: 产品供应部-计划中心 | C8: 产品供应部-计划中心 | D8: 管培生 | E8: 钟恩宝 | F8: 2026年07月 | G8: 产品供应部计划经理绩效考核方案 | H8: 部门关键项目完成率 | I8: 关键项目 | J8: 1 | K8: 90%%% | L8: 总目标金额5720， 实际损耗金额2119 | M8: 0.9 | N8: 0.4 | O8: 0.9 | P8: 1.00971 | Q8: 1.01 | R8: 5525.6 | S8: 5525.6 | T8: 5000 | U8: 子指标名称 | V8: 子指标说明 | W8: 子指标目标 | X8: 子指标完成量 | Y8: 子指标完成情况说明 | Z8: 子指标完成率 | AA8: 子指标权重 | AB8: 子指标得分
A9: FD-092488 | B9: 产品供应部-计划中心 | C9: 产品供应部-计划中心 | D9: 管培生 | E9: 林杜明 | F9: 2026年07月 | G9: 产品供应部计划经理绩效考核方案 | H9: 生产履约目标完成率 | I9: 沪汇加工厂履约率 | J9: 1 | K9: 1 | L9: 沪汇7月份履约率100% | M9: 1 | N9: 0.3 | O9: 1 | P9: 0.89 | Q9: 0.91 | R9: 0 | S9: 0 | T9: 5000 | U9: 子指标名称 | V9: 子指标说明 | W9: 子指标目标 | X9: 子指标完成量 | Y9: 子指标完成情况说明 | Z9: 子指标完成率 | AA9: 子指标权重 | AB9: 子指标得分
A10: OD-002451 | B10: 人资行政部-组织发展中心 | C10: 人资行政部-组织发展中心 | D10: SSC助理 | E10: 陆颖 | F10: 2026年07月 | G10: 人资行政部-组织发展中心-SSC助理 | H10: 例行工作及时率 | I10: 按照对应节点完成各项工作 | J10: 1 | K10: 0 | L10: 已按照节点完成 | M10: 1 | N10: 0.5 | O10: 1 | P10: 1 | Q10: 1 | R10: 1500 | S10: 1500 | T10: 1500 | U10: 转正管理及时率 | V10: 6.30完成7、8月转正名单更新；7.10完成6月转正考勤更新；7.29完成6月转正结果更新；7.30完成8、9月转正名单更新 | X10: 子指标完成量 | Y10: 6.30更新7、8月预计转正名单，7.9更新转正考勤，7.29更新转正结果，7.30更新8、9月转正名单 | Z10: 1 | AA10: 0.2 | AB10: 1
A11: OD-000664 | B11: 人资行政部-组织发展中心 | C11: 人资行政部-组织发展中心 | D11: SSC助理 | E11: 宋月 | F11: 2026年07月 | G11: 人资行政部-组织发展中心-SSC助理 | H11: 例行工作及时率 | I11: 季度评级：跟进OA岛民上级提交 定计划文档提交率80% 7.13完成绩效数据整理 | J11: 1 | K11: 0 | L11: 季度评级：跟进OA岛民上级提交 定计划文档提交率80% 7.13完成绩效数据整理 7.10完成 | M11: 1.075 | N11: 0.5 | O11: 1.075 | P11: 1.0285 | Q11: 1.03 | R11: 2060 | S11: 2060 | T11: 2000 | U11: 绩效数据汇总分析完成率 | X11: 准确完成 | Y11: 7.10完成 | Z11: 1.2 | AA11: 0.6 | AB11: 1.2
A12: OD-008606 | B12: 人资行政部-组织发展中心 | C12: 人资行政部-组织发展中心 | D12: SSC助理 | E12: 吴瑶华 | F12: 2026年07月 | G12: 人资行政部-组织发展中心-SSC助理 | H12: 例行工作及时率 | I12: 1、离职流程完结率 2、三方处理及时率 3、社保公积金缴纳及时率 3、社保公积金补缴及时率 4、生育津贴处理及时率 5、工伤申报处理及时率 | J12: 1 | K12: 0 | L12: 及时完成 | M12: 1 | N12: 0.5 | O12: 1 | P12: 0.9375 | Q12: 0.94 | R12: 1410 | S12: 1410 | T12: 1500 | U12: 离职流程完结率 | V12: - 计算公式：离职流程完结及时率=离职流程完结数/当月离职总人数*100% 1. 离职流程准时完结数：账号注销日期为最后工作日结束后的三个工作日内 账号注销：需要业务部门确认工作交接、财务确认报销流程完结、行政确认固定资产交接完结、组发核对考勤完结，开具离职证明后注销 1. 当月离职总人数：含正式、试用期、实习期、兼职等所有人员，以【飞书审批-离职交接、实习结束交接申请】数据为准 | W12: 1 | X12: 100 | Y12: "6.29-6.30离职24人，7月离职145人，剔除7.30及之后25人，离职的离职完结3天内的达126/144人，占比87.5% 岛民离职进度跟进表-SSC专用 " | Z12: 0.875 | AA12: 0.3 | AB12: 1
A13: FD-155599 | B13: 人资行政部-组织发展中心 | C13: 人资行政部-组织发展中心 | D13: COE专家 | E13: 王雅丽 | F13: 2026年07月 | G13: 人资行政部-组织发展中心-COE专家、SSC专家202606 | H13: 价值创造类 | I13: 社保公积金年度调基方案 | K13: 已完成 | L13: 及时完成 | M13: 1 | N13: 0.5 | O13: 1 | P13: 1 | Q13: 1 | R13: 3386 | S13: 3386 | T13: 3000 | U13: 社保公积金年度调基方案 | X13: 已完成 | Y13: 无误 | Z13: 1 | AA13: 1 | AB13: 1
A14: FD-156792 | B14: 人资行政部-组织发展中心 | C14: 人资行政部-组织发展中心 | D14: COE专家 | E14: 宫兆宜 | F14: 2026年07月 | G14: 人资行政部-组织发展中心-COE专家、SSC专家202606 | H14: 价值创造类 | I14: 绩效访谈的开展&分析报告的输出 | K14: 1 | L14: 完成方案的初版报告的生成（AI版本） | M14: 1 | N14: 0.7 | O14: 1 | P14: 1 | Q14: 1 | R14: 3386 | S14: 3386 | T14: 3000 | U14: 交付进度完成率 | X14: 1 | Y14: 无误 | Z14: 1 | AA14: 0.4 | AB14: 1
A15: FD-154391 | B15: 人资行政部-组织发展中心 | C15: 人资行政部-组织发展中心 | D15: SSC专家 | E15: 胡涵冰 | F15: 2026年07月 | G15: 人资行政部-组织发展中心-COE专家、SSC专家202606 | H15: 合同签订及时率 | I15: 把控跟进合同及协议签订流程 | J15: 1 | K15: 0.7943 | L15: 实际合同签订及时率为79.43% | M15: 0.7943 | N15: 0.3 | O15: 0.6354 | P15: 0.85829 | Q15: 0.81 | R15: 2128 | S15: 2128 | T15: 2200 | U15: 交付质量完成率 | X15: 100 | Y15: 无误 | Z15: 1 | AA15: 0.6 | AB15: 1
A16: FD-155628 | B16: 人资行政部-组织发展中心 | C16: 人资行政部-组织发展中心 | D16: 管培生 | E16: 杨宁 | F16: 2026年07月 | G16: 人资行政部-组织发展中心-COE专家、SSC专家202606 | H16: 关键工作完成率 | I16: 人岗匹配Q3分析报告 + 优化方案 | J16: 100 | K16: 80 | L16: 人岗匹配优化方案3.0+人才评估体系思考2.0 | M16: 0.8 | N16: 0.6 | O16: 0.8 | P16: 0.8 | Q16: 0.8 | R16: 4300 | S16: 4300 | T16: 5000 | U16: 交付质量完成率 | X16: 100 | Y16: 无误 | Z16: 1 | AA16: 0.6 | AB16: 1
A17: FD-083986 | B17: 新品牌事业部-设计中心 | C17: 新品牌事业部-设计中心 | D17: 产品设计师 | E17: 罗亦晨 | F17: 2026年07月 | G17: 新品牌事业部-设计中心-产品组各岗位设计师月度绩效考核方案 | H17: 核心设计项目产出 | I17: 可麦纸箱设计升级3.0 设计定版，下推打样 | J17: 1 | K17: 80 | M17: 0.4 | N17: 0.4 | O17: 0.4 | P17: 0.67 | Q17: 1.07 | R17: 3200 | S17: 3200 | T17: 2800 | U17: 交付质量完成率 | X17: 100 | Y17: 无误 | Z17: 1 | AA17: 0.6 | AB17: 1
A18: FD-080197 | B18: 新品牌事业部-设计中心 | C18: 新品牌事业部-设计中心 | D18: 产品设计师 | E18: 邓力欣 | F18: 2026年07月 | G18: 新品牌事业部-设计中心-产品组各岗位设计师月度绩效考核方案 | H18: 核心设计项目产出 | I18: 可麦纸箱设计升级3.0 设计定版，下推打样 | J18: 100& | K18: 80 | M18: 1 | N18: 0.4 | O18: 1 | P18: 0.67 | Q18: 0.77 | R18: 2216 | S18: 2216 | T18: 2800 | U18: 交付质量完成率 | X18: 100 | Y18: 无误 | Z18: 1 | AA18: 0.6 | AB18: 1
A19: FD-088054 | B19: 新品牌事业部-设计中心 | C19: 新品牌事业部-设计中心 | D19: 产品设计师 | E19: 余楚薰 | F19: 2026年07月 | G19: 新品牌事业部-设计中心-产品组各岗位设计师月度绩效考核方案 | H19: 核心设计项目产出 | I19: 可麦纸箱设计升级3.0 设计定版，下推打样 | J19: 1 | K19: 80 | M19: 0.4 | N19: 0.4 | O19: 0.4 | P19: 0.58 | Q19: 0.68 | R19: 0 | S19: 0 | T19: 2800 | U19: 交付质量完成率 | X19: 100 | Y19: 无误 | Z19: 1 | AA19: 0.6 | AB19: 1
A20: FD-085640 | B20: 新品牌事业部-设计中心 | C20: 新品牌事业部-设计中心 | D20: 首席平面设计师 | E20: 谢志达 | F20: 2026年07月 | G20: 新品牌事业部-设计中心-平面组各岗位设计师月度绩效考核方案 | H20: 核心设计项目产出 | I20: AI应用设计的项目流程优化方案-营销AI视频自动化 | J20: 1 | K20: 40%%% | L20: 1 | M20: 1 | N20: 0.3 | O20: 0.3 | P20: 0.7 | Q20: 0.75 | R20: 3810 | S20: 3810 | T20: 5000 | U20: 交付质量完成率 | X20: 100 | Y20: 无误 | Z20: 1 | AA20: 0.6 | AB20: 1
A21: FD-084584 | B21: 新品牌事业部-设计中心 | C21: 新品牌事业部-设计中心 | D21: 资深平面设计师 | E21: 张盛源 | F21: 2026年07月 | G21: 新品牌事业部-设计中心-平面组各岗位设计师月度绩效考核方案 | H21: 核心设计项目产出 | I21: 凡岛季度荣誉榜kv设计 | J21: 1 | K21: 完成荣誉榜KV*1+人物组合*3%%% | L21: 100%已完成 | M21: 1 | N21: 0.3 | O21: 1 | P21: 0.73 | Q21: 0.83 | R21: 2870 | S21: 2870 | T21: 3000 | U21: 交付质量完成率 | X21: 100 | Y21: 无误 | Z21: 1 | AA21: 0.6 | AB21: 1
A22: FD-084304 | B22: 新品牌事业部-设计中心 | C22: 新品牌事业部-设计中心 | D22: 资深平面设计师 | E22: 苏秋英 | F22: 2026年07月 | G22: 新品牌事业部-设计中心-平面组各岗位设计师月度绩效考核方案 | H22: 日常平面工单完成率 | I22: IRY日常平面工单完成率 100% | J22: 1 | K22: 100%% | L22: 100 | M22: 1 | N22: 0.3 | O22: 1 | P22: 1 | Q22: 1 | R22: 3400 | S22: 3400 | T22: 3000 | U22: 交付质量完成率 | X22: 100 | Y22: 无误 | Z22: 1 | AA22: 0.6 | AB22: 1
A23: FD-155034 | B23: 凡岛大学 | C23: 凡岛大学 | D23: 培训讲师 | E23: 蒋欣 | F23: 2026年07月 | G23: 凡岛大学-培训讲师绩效考核方案2606 | H23: 管理类培训-课程交付完成 | I23: 按计划完成管理课程开发100%(权重30%) | J23: 8门 | K23: 8门 | L23: 已完成8门课程的开发，并交付落地 | M23: 1 | N23: 0.3 | O23: 1 | P23: 1 | Q23: 1 | R23: 2000 | S23: 2000 | T23: 2000 | U23: 交付质量完成率 | X23: 100 | Y23: 无误 | Z23: 1 | AA23: 0.6 | AB23: 1
A24: FD-203809 | B24: 凡岛大学 | C24: 凡岛大学 | D24: 培训讲师 | E24: 王无双 | F24: 2026年07月 | G24: 凡岛大学-培训讲师绩效考核方案2606 | H24: 专业技能体系得分 | I24: 人资市场公关品牌管理部7月考核 | J24: 20次 | K24: 完成部门考核100%次 | L24: 课程： 高级经理课程《品牌在全渠道的管理》--辛小甜总监，4.72 《凡岛之路》--校长，4.9 《管理者的自我修炼》--陈一萌总监 5.0 《激活组织氛围》--校长 5.0 《价值判断与价值共识》--侯庆福总监，4.76 《品牌管理与产品》--廖丫，4.810 《品牌营销与传播》--唐娟总监，4.952 《渠道认知与实操》--松梅总监，5.0 | M24: 1 | N24: 0.15 | O24: 1 | P24: 0.83 | Q24: 0.83 | R24: 2490 | S24: 2490 | T24: 3000 | U24: 人资考核落地执行率 | V24: 考核落地执行率=当月实际考核设计落地数/当月考核设计落地目标数*100% | W24: 1 | X24: 完成部门考核100% | Y24: 无误 | Z24: 1 | AA24: 0.5 | AB24: 1
A25: OD-007504 | B25: 凡岛大学 | C25: 凡岛大学 | D25: 课程助教 | E25: 梁夏晴 | F25: 2026年07月 | G25: 凡岛大学-课程助教绩效方案 | H25: 新岛民总优质授课率 | I25: 组织7月三期新岛民培训 | J25: 0.8 | K25: 0.8667 | L25: 三期15门课程，13门课程达到优质授课 | M25: 1.08 | N25: 0.3 | O25: 1.08 | P25: 1.024 | Q25: 1.02 | R25: 2040 | S25: 2040 | T25: 2000 | U25: 品牌管理考核落地执行率 | V25: 考核落地执行率=当月实际考核设计落地数/当月考核设计落地目标数*100% | W25: 100 | X25: 完成部门考核100% | Y25: 无误 | Z25: 1 | AA25: 0.25 | AB25: 100
A26: FD-222057 | B26: AI效率流程部-AI效率流程D中心 | C26: AI效率流程部-AI效率流程D中心 | D26: AIBP | E26: 朱嘉琳 | F26: 2026年07月 | G26: 【AI效率流程D中心】绩效方案-fando推广版 | H26: skill达成数量 | I26: 帮业务搭建8个可复用的高价值skill | J26: 8个 | K26: 18个 | L26: 顺利将赛程推进至公司初赛，并宣发完成 | M26: 2.25 | N26: 0.4 | O26: 1.5 | P26: 1.669283 | Q26: 1.38 | R26: 4080 | S26: 4080 | T26: 3400 | U26: 品牌管理考核落地执行率 | V26: 考核落地执行率=当月实际考核设计落地数/当月考核设计落地目标数*100% | W26: 100 | X26: 完成部门考核100% | Y26: 无误 | Z26: 1 | AA26: 0.25 | AB26: 100
A27: OD-001113 | B27: 人资行政部-直播招聘中心 | C27: 人资行政部-直播招聘中心 | D27: 招聘专员 | E27: 蓝煜钧 | F27: 2026年07月 | G27: 直播招聘中心-高级主播模块-绩效考核方案 | H27: 个人猎聘目标完成率 | I27: 高级主播试播完成 | J27: 2人 | K27: 0 | L27: 顺利将赛程推进至公司初赛，并宣发完成 | M27: 0 | N27: 0.6 | O27: 0 | P27: 0.4 | Q27: 0.48 | R27: 1440 | S27: 1440 | T27: 3000 | U27: 品牌管理考核落地执行率 | V27: 考核落地执行率=当月实际考核设计落地数/当月考核设计落地目标数*100% | W27: 100 | X27: 完成部门考核100% | Y27: 无误 | Z27: 1 | AA27: 0.25 | AB27: 100
A28: FD-223714 | B28: AI效率流程部-AI效率流程D中心 | C28: AI效率流程部-AI效率流程D中心 | D28: AIBP | E28: 叶森莹 | F28: 2026年07月 | G28: 【AI效率流程D中心】绩效方案-fando推广版 | H28: skill达成数量 | I28: 营销段高价值可复用的SKILL | J28: 8个 | K28: 18个个 | L28: 入职1主播 | M28: 2.25 | N28: 0.4 | O28: 1.5 | P28: 1.233183 | Q28: 1.28 | R28: 2720 | S28: 2720 | T28: 3400 | U28: 品牌管理考核落地执行率 | V28: 考核落地执行率=当月实际考核设计落地数/当月考核设计落地目标数*100% | W28: 100 | X28: 完成部门考核100% | Y28: 无误 | Z28: 1 | AA28: 0.25 | AB28: 100
A29: FD-228363 | B29: AI效率流程部-AI效率流程D中心 | C29: AI效率流程部-AI效率流程D中心 | D29: AI工程师 | E29: 许国杨 | F29: 2026年07月 | G29: 6月-AI效率流程D中心绩效方案 | H29: 项目效果 | I29: 【AI微医生】24H新粉退后转化率 | J29: 0.11 | K29: 0.1312 | L29: Al: 24H-13.12% 【精英池:24H- 10.85%】 | M29: 1.1927 | N29: 0.2 | O29: 1.312 | P29: 1.04904 | Q29: 0.94 | R29: 4000 | S29: 4000 | T29: 4000 | U29: 品牌管理考核落地执行率 | V29: 考核落地执行率=当月实际考核设计落地数/当月考核设计落地目标数*100% | W29: 100 | X29: 完成部门考核100% | Y29: 无误 | Z29: 1 | AA29: 0.25 | AB29: 100
A30: FD-229844 | B30: AI效率流程部-AI效率流程D中心 | C30: AI效率流程部-AI效率流程D中心 | D30: AI工程师 | E30: 许阳 | F30: 2026年07月 | G30: 6月-AI效率流程D中心绩效方案 | H30: 项目效果 | I30: 【AI微医生】24H新粉退后转化率 | J30: 0.11 | K30: 0.1312 | L30: AI：24H-13.12% 【精英池：24H-10.85%】 | M30: 1.1927 | N30: 0.2 | O30: 1.312 | P30: 1.04904 | Q30: 0.94 | R30: 4000 | S30: 4000 | T30: 4000 | U30: 品牌管理考核落地执行率 | V30: 考核落地执行率=当月实际考核设计落地数/当月考核设计落地目标数*100% | W30: 100 | X30: 完成部门考核100% | Y30: 无误 | Z30: 1 | AA30: 0.25 | AB30: 100
A31: FD-227696 | B31: AI效率流程部-AI效率流程D中心 | C31: AI效率流程部-AI效率流程D中心 | D31: AIBP | E31: 张怡 | F31: 2026年07月 | G31: 6月-AI效率流程D中心绩效方案 | H31: 项目效果 | I31: 【AI微医生】新粉转化率11% | J31: 0.11 | K31: 13.12%% | L31: 1. 优化新粉不回复情况，更新价格疑虑skill，重构delay工具 2. 完成新粉商用需求对齐与规划 扣退后AI转化率：当天-11.95% 24H-13.12% | M31: 1.192 | N31: 0.2 | O31: 1.31 | P31: 1.0484 | Q31: 0.94 | R31: 3400 | S31: 3400 | T31: 3400 | U31: 品牌管理考核落地执行率 | V31: 考核落地执行率=当月实际考核设计落地数/当月考核设计落地目标数*100% | W31: 100 | X31: 完成部门考核100% | Y31: 无误 | Z31: 1 | AA31: 0.25 | AB31: 100
A32: FD-224360 | B32: AI效率流程部-AI效率流程D中心 | C32: AI效率流程部-AI效率流程D中心 | D32: AI工程师 | E32: 余粤 | F32: 2026年07月 | G32: 6月-AI效率流程D中心绩效方案 | H32: 项目效果 | I32: 【AI微医生】扣退后24H新粉转化率 | J32: 0.11 | K32: 0.1312 | L32: 1. 灵活激活上线，优化skill 2. 下单后总结修改地址和备注方案上线：可对于下单前用户提出的要求进行修改响应 3. 长期维护新增激活skill，"long-term-activation"，主要是根据不同用户类型去生成个性化激活话术，目前针对新粉未成交和使用过敏退款的用户都可生成较合适的激活话术 4. 优化月度活动激活 | M32: 1.1927 | N32: 0.2 | O32: 1.312 | P32: 1.04904 | Q32: 0.94 | R32: 5000 | S32: 5000 | T32: 5000 | U32: 品牌管理考核落地执行率 | V32: 考核落地执行率=当月实际考核设计落地数/当月考核设计落地目标数*100% | W32: 100 | X32: 完成部门考核100% | Y32: 无误 | Z32: 1 | AA32: 0.25 | AB32: 100
A33: FD-184644 | B33: 公共事务与品牌传播部 | C33: 公共事务与品牌传播部 | D33: 品牌公关经理 | E33: 黄靖雯 | F33: 2026年07月 | G33: 公共事务与品牌传播部-品牌公关经理岗位绩效方案 | H33: 项目管理关键节点完成率 | I33: fando宣传内容制作及上线 | J33: 1 | L33: 7月共计产出30张宣传海报，实战案例视频1条，凡动表情包1.0已上线（包含16个形象）。 内宣部分各楼层广告机以及飞书表情商店均已上线，外宣部分均已发布。 | M33: 1 | N33: 0.8 | O33: 1 | P33: 1 | Q33: 1 | R33: 5000 | S33: 5000 | T33: 5000 | U33: 品牌管理考核落地执行率 | V33: 考核落地执行率=当月实际考核设计落地数/当月考核设计落地目标数*100% | W33: 100 | X33: 完成部门考核100% | Y33: 无误 | Z33: 1 | AA33: 0.25 | AB33: 100
A34: FD-181227 | B34: 公共事务与品牌传播部 | C34: 公共事务与品牌传播部 | D34: 品牌公关经理 | E34: 杨颖晖 | F34: 2026年07月 | G34: 公共事务与品牌传播部-品牌公关经理岗位绩效方案 | H34: 项目管理关键节点完成率 | I34: KONO KOC小红书合作 | J34: 1 | L34: 笔记合作量：实际 100，目标 90，达成率 111.11% 笔记收片量：实际 86，目标 90，达成率 95.56% | M34: 1.0334 | N34: 0.25 | O34: 1.03 | P34: 1.000005 | Q34: 0.99 | R34: 4950 | S34: 4950 | T34: 5000 | U34: 品牌管理考核落地执行率 | V34: 考核落地执行率=当月实际考核设计落地数/当月考核设计落地目标数*100% | W34: 100 | X34: 完成部门考核100% | Y34: 无误 | Z34: 1 | AA34: 0.25 | AB34: 100
A35: FD-188611 | B35: 公共事务与品牌传播部 | C35: 公共事务与品牌传播部 | D35: 品牌公关经理 | E35: 郑胡斌 | F35: 2026年07月 | G35: 公共事务与品牌传播部-品牌公关经理岗位绩效方案 | H35: 项目管理关键节点完成率 | I35: WIS、赫系7月奖项申报和荣誉传播 | L35: 由于粤妆甄品项目终止参赛，其余7月周期内奖项申报均已完成，已完成奖项申报工作2品牌4个，公共传播事件2个； | M35: 1 | N35: 0.3 | O35: 1 | P35: 1 | Q35: 1 | R35: 0 | S35: 0 | T35: 3000 | U35: 品牌管理考核落地执行率 | V35: 考核落地执行率=当月实际考核设计落地数/当月考核设计落地目标数*100% | W35: 100 | X35: 完成部门考核100% | Y35: 无误 | Z35: 1 | AA35: 0.25 | AB35: 100
A36: FD-181490 | B36: 公共事务与品牌传播部 | C36: 公共事务与品牌传播部 | D36: 舆情数据经理 | E36: 吴晓升 | F36: 2026年07月 | G36: 公共事务与品牌传播部舆情数据经理绩效考核方案 | H36: 策略执行达成率 | I36: 跟踪各项核心任务的实际完成进度与质量，按月统计执行达成率，输出复盘报告并针对未达标项制定改进措施。 | J36: 0.9 | L36: 0.2 | M36: 1 | N36: 0.2 | O36: 1 | P36: 1 | Q36: 1 | R36: 2000 | S36: 2000 | T36: 2000 | U36: 品牌管理考核落地执行率 | V36: 考核落地执行率=当月实际考核设计落地数/当月考核设计落地目标数*100% | W36: 100 | X36: 完成部门考核100% | Y36: 无误 | Z36: 1 | AA36: 0.25 | AB36: 100
A37: FD-181047 | B37: 公共事务与品牌传播部 | C37: 公共事务与品牌传播部 | D37: 公共事务经理 | E37: 周璐涵 | F37: 2026年07月 | G37: 公共事务与品牌传播部公共事务经理绩效考核方案 | H37: 双向合作价值次数 | I37: 媒体双向合作 | J37: 4 | K37: 4 | L37: 0.2 | M37: 1 | N37: 0.4 | O37: 1 | P37: 1 | Q37: 1 | R37: 5000 | S37: 5000 | T37: 5000 | U37: 品牌管理考核落地执行率 | V37: 考核落地执行率=当月实际考核设计落地数/当月考核设计落地目标数*100% | W37: 100 | X37: 完成部门考核100% | Y37: 无误 | Z37: 1 | AA37: 0.25 | AB37: 100
A38: FD-094330 | B38: 产品供应部-供应中心 | C38: 产品供应部-供应中心 | D38: 供应链经理 | E38: 陆永泉 | F38: 2026年07月 | G38: 【产品供应部-供应中心】-供应链经理、管培生、见习高级经理绩效考核方案 | H38: 订单履约指标 | I38: 原料模块订单履约完成率=成品原料履约款数/当月总核算成品款数 | J38: 1 | K38: 0.9906 | L38: 合计107款，成品履约106款，履约率99.06% | M38: 0.9906 | N38: 0.5 | O38: 1 | P38: 0.9953 | Q38: 1.14 | R38: 3348.84 | S38: 3348.84 | T38: 3000 | U38: 品牌管理考核落地执行率 | V38: 考核落地执行率=当月实际考核设计落地数/当月考核设计落地目标数*100% | W38: 100 | X38: 完成部门考核100% | Y38: 无误 | Z38: 1 | AA38: 0.25 | AB38: 100
A39: FD-080606 | B39: 产品供应部-供应中心 | C39: 产品供应部-供应中心 | D39: 供应链经理 | E39: 龙美莹 | F39: 2026年07月 | G39: 【产品供应部-供应中心】-供应链经理、管培生、见习高级经理绩效考核方案 | H39: 订单履约指标 | I39: 本月目标 | J39: 0.98 | K39: 0.9957 | L39: 送货总条数231，未履约1条 | M39: 1 | N39: 0.4 | O39: 1 | P39: 0.98314 | Q39: 1.14 | R39: 3069.77 | S39: 3069.77 | T39: 3000 | U39: 品牌管理考核落地执行率 | V39: 考核落地执行率=当月实际考核设计落地数/当月考核设计落地目标数*100% | W39: 100 | X39: 完成部门考核100% | Y39: 无误 | Z39: 1 | AA39: 0.25 | AB39: 100
A40: FD-153639 | B40: 产品供应部-供应中心 | C40: 产品供应部-供应中心 | D40: 供应链经理 | E40: 翁承梅 | F40: 2026年07月 | G40: 【产品供应部-供应中心】-供应链经理、管培生、见习高级经理绩效考核方案 | H40: 订单履约指标 | I40: 订单履约率 | J40: 0.99 | K40: 0.9741 | L40: 1、金冠-隐形水润经典款24片 2、雅纯-隐形水润经典款十片3、从化-KONO经典洗护套装（彩盒） | M40: 0.9839 | N40: 0.5 | O40: 0.8855 | P40: 0.99195 | Q40: 0.97 | R40: 2511.63 | S40: 2511.63 | T40: 3000 | U40: 品牌管理考核落地执行率 | V40: 考核落地执行率=当月实际考核设计落地数/当月考核设计落地目标数*100% | W40: 100 | X40: 完成部门考核100% | Y40: 无误 | Z40: 1 | AA40: 0.25 | AB40: 100
...

Sheet 整合-原始
A1: 工号旧 | B1: 工号-新 | C1: 部门 | D1: 中心查找 | E1: 岗位查找 | F1: 姓名 | G1: 总完成率 | H1: 总得分 | I1: 总奖金 | J1: 绩效基数 | K1: 新工号查找 | L1: 核查 | M1: 部门查找 | N1: 核查 | O1: 中心查找 | P1: 核查 | Q1: 岗位查找 | R1: 核查 | S1: 工号旧 | T1: 核查
B2: FD-043687 | C2: 品牌创意部-直播中心 | D2: 品牌创意部-直播中心 | E2: 主播 | F2: 张丹 | G2: 1 | H2: 373 | I2: 13000 | J2: 10000
B3: FD-031919 | C3: 品牌创意部-直播中心 | D3: 品牌创意部-直播中心 | E3: 高级主播 | F3: 庄少丽 | G3: 1 | H3: 343 | I3: 60000 | J3: 55000
B4: FD-043134 | C4: 品牌创意部-直播中心 | D4: 品牌创意部-直播中心 | E4: 主播 | F4: 黄羽丹 | G4: 1 | H4: 321.5 | I4: 40500 | J4: 10000
B5: FD-042958 | C5: 品牌创意部-直播中心 | D5: 品牌创意部-直播中心 | E5: 高级主播 | F5: 赵雅萱 | G5: 1 | H5: 319 | I5: 30000 | J5: 100000
B6: FD-041967 | C6: 品牌创意部-直播中心 | D6: 品牌创意部-直播中心 | E6: 高级主播 | F6: 赵弘睿 | G6: 1 | H6: 313.5 | I6: 20500 | J6: 55000
B7: FD-047686 | C7: 品牌创意部-直播中心 | D7: 品牌创意部-直播中心 | E7: 主播 | F7: 辛宜静 | G7: 1 | H7: 310 | I7: 10000 | J7: 10000
B8: FD-046625 | C8: 品牌创意部-直播中心 | D8: 品牌创意部-直播中心 | E8: 主播 | F8: 赵凯悦 | G8: 1 | H8: 293 | I8: 8200 | J8: 10000
B9: FD-040324 | C9: 品牌创意部-直播中心 | D9: 品牌创意部-直播中心 | E9: 主播 | F9: 魏海燕 | G9: 1 | H9: 288 | I9: 200 | J9: 10000
B10: FD-047330 | C10: 品牌创意部-直播中心 | D10: 品牌创意部-直播中心 | E10: 主播 | F10: 雷丽娟 | G10: 1 | H10: 280 | I10: 6000 | J10: 10000
B11: FD-041335 | C11: 品牌创意部-直播中心 | D11: 品牌创意部-直播中心 | E11: 主播 | F11: 张郑庆 | G11: 1 | H11: 265.5 | I11: 2500 | J11: 10000
B12: FD-041568 | C12: 品牌创意部-直播中心 | D12: 品牌创意部-直播中心 | E12: 高级主播 | F12: 周晓纯 | G12: 1 | H12: 254 | I12: 14000 | J12: 55000
B13: FD-045322 | C13: 品牌创意部-直播中心 | D13: 品牌创意部-直播中心 | E13: 主播 | F13: 吴雨璠 | G13: 1 | H13: 254 | I13: 0 | J13: 10000
... B171: FD-017532 | C171: 市场拓展部 | D171: 市场拓展部 | E171: 总监助理 | F171: 马菲阳 | G171: 1.0894 | H171: 1.2 | I171: 4000 | J171: 3000
F172: 朱丹萍 | G172: 1.2 | H172: 1.2 | I172: 5400 | J172: 5000
B173: FD-091571 | C173: 产品供应部-物流中心 | D173: 产品供应部-物流中心 | E173: 物流高级经理 | F173: 吴永星 | G173: 1.18696 | H173: 1.19 | I173: 5200 | J173: 5000
B174: FD-036124 | C174: 广告策划部-创新C中心 | D174: 广告策划部-创新C中心 | E174: 营销高级经理 | F174: 唐基翔 | G174: 1.191 | H174: 1.19 | I174: 5400 | J174: 5000
B175: FD-054711 | C175: 市场拓展部-先锋中心 | D175: 市场拓展部-先锋中心 | E175: 市场高级经理 | F175: 苏静微 | G175: 2.44875 | H175: 1.19 | I175: 6160 | J175: 5000
B176: FD-051657 | C176: 市场拓展部-媒介中心 | D176: 市场拓展部-媒介中心 | E176: 管培生 | F176: 冯馨怡 | G176: 0.880912 | H176: 1.19 | I176: 3653.62 | J176: 5000
B177: FD-056244 | C177: 市场拓展部-媒介中心 | D177: 市场拓展部-媒介中心 | E177: 商务PR | F177: 李欣 | G177: 0.87908 | H177: 1.19 | I177: 2316.82 | J177: 2000
F178: 吴永星 | G178: 1.187 | H178: 1.19 | I178: 5200 | J178: 5000
B179: FD-157175 | C179: 人资行政部-综合招聘中心 | D179: 人资行政部-综合招聘中心 | E179: 招聘经理 | F179: 陈学锦 | G179: 1.175 | H179: 1.18 | I179: 4454.55 | J179: 3000
B180: FD-096682 | C180: 产品供应部-采购中心 | D180: 产品供应部-采购中心 | E180: 采购经理 | F180: 巫文鑫 | G180: 1.222222 | H180: 1.18 | I180: 3461.54 | J180: 3000
B181: FD-044712 | C181: 电商发展部-赫系渠道A中心 | D181: 电商发展部-赫系渠道A中心 | E181: 电商高级经理 | F181: 许立榕 | G181: 1.120302 | H181: 1.18 | I181: 8000 | J181: 5000
B182: FD-098144 | C182: 产品供应部-供应中心 | D182: 产品供应部-供应中心 | E182: 供应链经理 | F182: 李红菊 | G182: 0.97492 | H182: 1.17 | I182: 3627.91 | J182: 3000
B183: FD-107532 | C183: 凡岛研究院-配方研究实验室 | D183: 凡岛研究院-配方研究实验室 | E183: 研发工程师 | F183: 王嘉俊 | G183: 1 | H183: 1.17 | I183: 2457 | J183: 3000
B184: FD-021226 | C184: 品牌营销部-营销中心J | D184: 品牌营销部-营销中心J | E184: 视频编辑 | F184: 唐茹 | G184: 1.449 | H184: 1.17 | I184: 5520 | J184: 2000
B185: FD-057590 | C185: 市场拓展部-明星中心 | D185: 市场拓展部-明星中心 | E185: 管培生 | F185: 张媛 | G185: 1.21286 | H185: 1.17 | I185: 4000 | J185: 5000
B186: FD-043442 | C186: 品牌创意部-赫系营销A中心 | D186: 品牌创意部-赫系营销A中心 | E186: 营销经理 | F186: 谭航 | G186: 1.58961 | H186: 1.17 | I186: 5758.6 | J186: 5000
B187: FD-082125 | C187: 新品牌事业部-品牌管理中心 | D187: 新品牌事业部-品牌管理中心 | E187: 品牌高级经理 | F187: 林少瑶 | G187: 1.172 | H187: 1.17 | I187: 6460 | J187: 3000
B188: FD-125310 | C188: 电商发展部-设计中心 | D188: 电商发展部-设计中心 | E188: 首席平面设计师 | F188: 谢海燕 | G188: 0.7175 | H188: 1.17 | I188: 6400 | J188: 4000
B189: FD-079664 | C189: 线下渠道部-KONO-KONO销售A中心-华东区 | D189: 线下渠道部-KONO-KONO销售A中心-华东区 | E189: KA商务经理 | F189: 高智慧 | G189: 1.183 | H189: 1.16 | I189: 8638.35 | J189: 6000
B190: FD-074107 | C190: 线下渠道部-WIS-WIS销售B中心 | D190: 线下渠道部-WIS-WIS销售B中心 | E190: 零售高级经理 | F190: 华珊 | G190: 2.05047 | H190: 1.15 | I190: 9291.67 | J190: 5000
... B223: FD-013392 | C223: 品牌创意部 | D223: 品牌创意部 | E223: 总监助理 | F223: 林睿媛 | G223: 1.1036 | H223: 1.1 | I223: 0 | J223: 3000
F224: 黄晓莲 | G224: 1.099 | H224: 1.1 | I224: 2200 | J224: 2000
F225: 谢昊 | G225: 1.1 | H225: 1.1 | I225: 5200 | J225: 5000
B226: FD-077703 | C226: 线下渠道部-渠道运作中心 | D226: 线下渠道部-渠道运作中心 | E226: 市场监察经理 | F226: 蓝文阳 | G226: 1.105 | H226: 1.09 | I226: 2400 | J226: 3000
B227: FD-157065 | C227: 人资行政部-HRBP中心 | D227: 人资行政部-HRBP中心 | E227: HR经理 | F227: 霍雨佳 | G227: 0.98708 | H227: 1.09 | I227: 3629.03 | J227: 3000
B228: FD-092873 | C228: 人资行政部-从化中心 | D228: 人资行政部-从化中心 | E228: 行政专员 | F228: 邝少芬 | G228: 0.9665 | H228: 1.08 | I228: 864 | J228: 800
B229: FD-172589 | C229: 财务部-财务分析中心 | D229: 财务部-财务分析中心 | E229: 财务BP | F229: 宋霄宇 | G229: 0.93073 | H229: 1.08 | I229: 3692.31 | J229: 3000
...

Sheet 整合-校准（副本）
A1: 工号旧 | B1: 工号-新 | C1: 年份 | D1: 月份 | E1: 部门 | F1: 中心查找 | G1: 岗位查找 | H1: 姓名 | I1: 总完成率 | J1: 总得分 | K1: 总得分 | L1: 总奖金 | M1: 绩效基数 | N1: 新工号查找 | O1: 核查 | P1: 部门查找 | Q1: 核查 | R1: 中心查找 | S1: 核查 | U1: 岗位查找 | V1: 核查 | W1: 备注 | X1: 工号旧 | Y1: 核查
B2: FD-043687 | C2: 26年 | D2: 7月 | E2: 品牌创意部 | F2: 直播中心 | G2: 主播 | H2: 张丹 | I2: 1 | J2: 373 | K2: =K2:J2% | L2: 13000 | M2: 10000 | N2: {=_xlfn.XLOOKUP(H2,'OA名单'!C:C,'OA名单'!B:B,1)} | O2: =IF(N2=B2,1) | P2: {=_xlfn.XLOOKUP(N2,'OA名单'!B:B,'OA名单'!G:G)} | Q2: =IF(P2=E2,1) | R2: {=_xlfn.XLOOKUP(B2,'OA名单'!B:B,'OA名单'!F:F)} | S2: =IF(R2=F2,1) | U2: {=_xlfn.XLOOKUP(N2,'OA名单'!B:B,'OA名单'!E:E)} | V2: =IF(U2=G2,1) | Y2: =IF(X2=K2,1)
B3: FD-031919 | C3: 26年 | D3: 7月 | E3: 品牌创意部 | F3: 直播中心 | G3: 高级主播 | H3: 庄少丽 | I3: 1 | J3: 343 | K3: =K3:J3% | L3: 60000 | M3: 55000 | N3: {=_xlfn.XLOOKUP(H3,'OA名单'!C:C,'OA名单'!B:B,1)} | O3: =IF(N3=B3,1) | P3: {=_xlfn.XLOOKUP(N3,'OA名单'!B:B,'OA名单'!G:G)} | Q3: =IF(P3=E3,1) | R3: {=_xlfn.XLOOKUP(B3,'OA名单'!B:B,'OA名单'!F:F)} | S3: =IF(R3=F3,1) | U3: {=_xlfn.XLOOKUP(N3,'OA名单'!B:B,'OA名单'!E:E)} | V3: =IF(U3=G3,1)
B4: FD-043134 | C4: 26年 | D4: 7月 | E4: 品牌创意部 | F4: 直播中心 | G4: 主播 | H4: 黄羽丹 | I4: 1 | J4: 321.5 | K4: =K4:J4% | L4: 40500 | M4: 10000 | N4: {=_xlfn.XLOOKUP(H4,'OA名单'!C:C,'OA名单'!B:B,1)} | O4: =IF(N4=B4,1) | P4: {=_xlfn.XLOOKUP(N4,'OA名单'!B:B,'OA名单'!G:G)} | Q4: =IF(P4=E4,1) | R4: {=_xlfn.XLOOKUP(B4,'OA名单'!B:B,'OA名单'!F:F)} | S4: =IF(R4=F4,1) | U4: {=_xlfn.XLOOKUP(N4,'OA名单'!B:B,'OA名单'!E:E)} | V4: =IF(U4=G4,1)
B5: FD-042958 | C5: 26年 | D5: 7月 | E5: 品牌创意部 | F5: 直播中心 | G5: 高级主播 | H5: 赵雅萱 | I5: 1 | J5: 319 | K5: =K5:J5% | L5: 30000 | M5: 100000 | N5: {=_xlfn.XLOOKUP(H5,'OA名单'!C:C,'OA名单'!B:B,1)} | O5: =IF(N5=B5,1) | P5: {=_xlfn.XLOOKUP(N5,'OA名单'!B:B,'OA名单'!G:G)} | Q5: =IF(P5=E5,1) | R5: {=_xlfn.XLOOKUP(B5,'OA名单'!B:B,'OA名单'!F:F)} | S5: =IF(R5=F5,1) | U5: {=_xlfn.XLOOKUP(N5,'OA名单'!B:B,'OA名单'!E:E)} | V5: =IF(U5=G5,1)
B6: FD-041967 | C6: 26年 | D6: 7月 | E6: 品牌创意部 | F6: 直播中心 | G6: 高级主播 | H6: 赵弘睿 | I6: 1 | J6: 313.5 | K6: =K6:J6% | L6: 20500 | M6: 55000 | N6: {=_xlfn.XLOOKUP(H6,'OA名单'!C:C,'OA名单'!B:B,1)} | O6: =IF(N6=B6,1) | P6: {=_xlfn.XLOOKUP(N6,'OA名单'!B:B,'OA名单'!G:G)} | Q6: =IF(P6=E6,1) | R6: {=_xlfn.XLOOKUP(B6,'OA名单'!B:B,'OA名单'!F:F)} | S6: =IF(R6=F6,1) | U6: {=_xlfn.XLOOKUP(N6,'OA名单'!B:B,'OA名单'!E:E)} | V6: =IF(U6=G6,1)
B7: FD-047686 | C7: 26年 | D7: 7月 | E7: 品牌创意部 | F7: 直播中心 | G7: 主播 | H7: 辛宜静 | I7: 1 | J7: 310 | K7: =K7:J7% | L7: 10000 | M7: 10000 | N7: {=_xlfn.XLOOKUP(H7,'OA名单'!C:C,'OA名单'!B:B,1)} | O7: =IF(N7=B7,1) | P7: {=_xlfn.XLOOKUP(N7,'OA名单'!B:B,'OA名单'!G:G)} | Q7: =IF(P7=E7,1) | R7: {=_xlfn.XLOOKUP(B7,'OA名单'!B:B,'OA名单'!F:F)} | S7: =IF(R7=F7,1) | U7: {=_xlfn.XLOOKUP(N7,'OA名单'!B:B,'OA名单'!E:E)} | V7: =IF(U7=G7,1)
B8: FD-046625 | C8: 26年 | D8: 7月 | E8: 品牌创意部 | F8: 直播中心 | G8: 主播 | H8: 赵凯悦 | I8: 1 | J8: 293 | K8: =K8:J8% | L8: 8200 | M8: 10000 | N8: {=_xlfn.XLOOKUP(H8,'OA名单'!C:C,'OA名单'!B:B,1)} | O8: =IF(N8=B8,1) | P8: {=_xlfn.XLOOKUP(N8,'OA名单'!B:B,'OA名单'!G:G)} | Q8: =IF(P8=E8,1) | R8: {=_xlfn.XLOOKUP(B8,'OA名单'!B:B,'OA名单'!F:F)} | S8: =IF(R8=F8,1) | U8: {=_xlfn.XLOOKUP(N8,'OA名单'!B:B,'OA名单'!E:E)} | V8: =IF(U8=G8,1)
B9: FD-040324 | C9: 26年 | D9: 7月 | E9: 品牌创意部 | F9: 直播中心 | G9: 主播 | H9: 魏海燕 | I9: 1 | J9: 288 | K9: =K9:J9% | L9: 200 | M9: 10000 | N9: {=_xlfn.XLOOKUP(H9,'OA名单'!C:C,'OA名单'!B:B,1)} | O9: =IF(N9=B9,1) | P9: {=_xlfn.XLOOKUP(N9,'OA名单'!B:B,'OA名单'!G:G)} | Q9: =IF(P9=E9,1) | R9: {=_xlfn.XLOOKUP(B9,'OA名单'!B:B,'OA名单'!F:F)} | S9: =IF(R9=F9,1) | U9: {=_xlfn.XLOOKUP(N9,'OA名单'!B:B,'OA名单'!E:E)} | V9: =IF(U9=G9,1)
B10: FD-047330 | C10: 26年 | D10: 7月 | E10: 品牌创意部 | F10: 直播中心 | G10: 主播 | H10: 雷丽娟 | I10: 1 | J10: 280 | K10: =K10:J10% | L10: 6000 | M10: 10000 | N10: {=_xlfn.XLOOKUP(H10,'OA名单'!C:C,'OA名单'!B:B,1)} | O10: =IF(N10=B10,1) | P10: {=_xlfn.XLOOKUP(N10,'OA名单'!B:B,'OA名单'!G:G)} | Q10: =IF(P10=E10,1) | R10: {=_xlfn.XLOOKUP(B10,'OA名单'!B:B,'OA名单'!F:F)} | S10: =IF(R10=F10,1) | U10: {=_xlfn.XLOOKUP(N10,'OA名单'!B:B,'OA名单'!E:E)} | V10: =IF(U10=G10,1)
B11: FD-041335 | C11: 26年 | D11: 7月 | E11: 品牌创意部 | F11: 直播中心 | G11: 主播 | H11: 张郑庆 | I11: 1 | J11: 265.5 | K11: =K11:J11% | L11: 2500 | M11: 10000 | N11: {=_xlfn.XLOOKUP(H11,'OA名单'!C:C,'OA名单'!B:B,1)} | O11: =IF(N11=B11,1) | P11: {=_xlfn.XLOOKUP(N11,'OA名单'!B:B,'OA名单'!G:G)} | Q11: =IF(P11=E11,1) | R11: {=_xlfn.XLOOKUP(B11,'OA名单'!B:B,'OA名单'!F:F)} | S11: =IF(R11=F11,1) | U11: {=_xlfn.XLOOKUP(N11,'OA名单'!B:B,'OA名单'!E:E)} | V11: =IF(U11=G11,1)
B12: FD-041568 | C12: 26年 | D12: 7月 | E12: 品牌创意部 | F12: 直播中心 | G12: 高级主播 | H12: 周晓纯 | I12: 1 | J12: 254 | K12: =K12:J12% | L12: 14000 | M12: 55000 | N12: {=_xlfn.XLOOKUP(H12,'OA名单'!C:C,'OA名单'!B:B,1)} | O12: =IF(N12=B12,1) | P12: {=_xlfn.XLOOKUP(N12,'OA名单'!B:B,'OA名单'!G:G)} | Q12: =IF(P12=E12,1) | R12: {=_xlfn.XLOOKUP(B12,'OA名单'!B:B,'OA名单'!F:F)} | S12: =IF(R12=F12,1) | U12: {=_xlfn.XLOOKUP(N12,'OA名单'!B:B,'OA名单'!E:E)} | V12: =IF(U12=G12,1)
B13: FD-045322 | C13: 26年 | D13: 7月 | E13: 品牌创意部 | F13: 直播中心 | G13: 主播 | H13: 吴雨璠 | I13: 1 | J13: 254 | K13: =K13:J13% | L13: 0 | M13: 10000 | N13: {=_xlfn.XLOOKUP(H13,'OA名单'!C:C,'OA名单'!B:B,1)} | O13: =IF(N13=B13,1) | P13: {=_xlfn.XLOOKUP(N13,'OA名单'!B:B,'OA名单'!G:G)} | Q13: =IF(P13=E13,1) | R13: {=_xlfn.XLOOKUP(B13,'OA名单'!B:B,'OA名单'!F:F)} | S13: =IF(R13=F13,1) | U13: {=_xlfn.XLOOKUP(N13,'OA名单'!B:B,'OA名单'!E:E)} | V13: =IF(U13=G13,1)
B14: FD-044791 | C14: 26年 | D14: 7月 | E14: 品牌创意部 | F14: 直播中心 | G14: 主播 | H14: 王丽媛 | I14: 1 | J14: 249 | K14: =K14:J14% | L14: 16000 | M14: 10000 | N14: {=_xlfn.XLOOKUP(H14,'OA名单'!C:C,'OA名单'!B:B,1)} | O14: =IF(N14=B14,1) | P14: {=_xlfn.XLOOKUP(N14,'OA名单'!B:B,'OA名单'!G:G)} | Q14: =IF(P14=E14,1) | R14: {=_xlfn.XLOOKUP(B14,'OA名单'!B:B,'OA名单'!F:F)} | S14: =IF(R14=F14,1) | U14: {=_xlfn.XLOOKUP(N14,'OA名单'!B:B,'OA名单'!E:E)} | V14: =IF(U14=G14,1)
... B43: FD-031047 | C43: 26年 | D43: 7月 | E43: 广告策划部 | F43: 直播A中心 | G43: 主播 | H43: 王佳怡 | I43: 1 | J43: 100 | K43: =K43:J43% | L43: 0 | M43: 10000 | N43: {=_xlfn.XLOOKUP(H43,'OA名单'!C:C,'OA名单'!B:B,1)} | O43: =IF(N43=B43,1) | P43: {=_xlfn.XLOOKUP(N43,'OA名单'!B:B,'OA名单'!G:G)} | Q43: =IF(P43=E43,1) | R43: {=_xlfn.XLOOKUP(B43,'OA名单'!B:B,'OA名单'!F:F)} | S43: =IF(R43=F43,1) | U43: {=_xlfn.XLOOKUP(N43,'OA名单'!B:B,'OA名单'!E:E)} | V43: =IF(U43=G43,1)
B44: FD-042321 | C44: 26年 | D44: 7月 | E44: 品牌创意部 | F44: 直播中心 | G44: 直播助理 | H44: 陈真坪 | I44: 1 | J44: 100 | K44: =K44:J44% | L44: 1000 | M44: 1000 | N44: {=_xlfn.XLOOKUP(H44,'OA名单'!C:C,'OA名单'!B:B,1)} | O44: =IF(N44=B44,1) | P44: {=_xlfn.XLOOKUP(N44,'OA名单'!B:B,'OA名单'!G:G)} | Q44: =IF(P44=E44,1) | R44: {=_xlfn.XLOOKUP(B44,'OA名单'!B:B,'OA名单'!F:F)} | S44: =IF(R44=F44,1) | T44: {=_xlfn.XLOOKUP(B44,'系统-原始（副本）'!A:A,'系统-原始（副本）'!B:B)} | U44: {=_xlfn.XLOOKUP(N44,'OA名单'!B:B,'OA名单'!E:E)} | V44: =IF(U44=G44,1)
B45: FD-042172 | C45: 26年 | D45: 7月 | E45: 品牌创意部 | F45: 直播中心 | G45: 直播助理 | H45: 陈思思 | I45: 0.99315 | J45: 99.32 | K45: =K45:J45% | L45: 2200 | M45: 1000 | N45: {=_xlfn.XLOOKUP(H45,'OA名单'!C:C,'OA名单'!B:B,1)} | O45: =IF(N45=B45,1) | P45: {=_xlfn.XLOOKUP(N45,'OA名单'!B:B,'OA名单'!G:G)} | Q45: =IF(P45=E45,1) | R45: {=_xlfn.XLOOKUP(B45,'OA名单'!B:B,'OA名单'!F:F)} | S45: =IF(R45=F45,1) | T45: {=_xlfn.XLOOKUP(B45,'系统-原始（副本）'!A:A,'系统-原始（副本）'!B:B)} | U45: {=_xlfn.XLOOKUP(N45,'OA名单'!B:B,'OA名单'!E:E)} | V45: =IF(U45=G45,1)
B46: FD-043476 | C46: 26年 | D46: 7月 | E46: 品牌创意部 | F46: 直播中心 | G46: 直播助理 | H46: 袁志彬 | I46: 0.9929 | J46: 99.29 | K46: =K46:J46% | L46: 1750 | M46: 1000 | N46: {=_xlfn.XLOOKUP(H46,'OA名单'!C:C,'OA名单'!B:B,1)} | O46: =IF(N46=B46,1) | P46: {=_xlfn.XLOOKUP(N46,'OA名单'!B:B,'OA名单'!G:G)} | Q46: =IF(P46=E46,1) | R46: {=_xlfn.XLOOKUP(B46,'OA名单'!B:B,'OA名单'!F:F)} | S46: =IF(R46=F46,1) | U46: {=_xlfn.XLOOKUP(N46,'OA名单'!B:B,'OA名单'!E:E)} | V46: =IF(U46=G46,1)
B47: FD-035562 | C47: 26年 | D47: 7月 | E47: 广告策划部 | F47: 直播A中心 | G47: 直播助理 | H47: 赵晓旭 | I47: 0.9788 | J47: 98.88 | K47: =K47:J47% | L47: 1900 | M47: 1000 | N47: {=_xlfn.XLOOKUP(H47,'OA名单'!C:C,'OA名单'!B:B,1)} | O47: =IF(N47=B47,1) | P47: {=_xlfn.XLOOKUP(N47,'OA名单'!B:B,'OA名单'!G:G)} | Q47: =IF(P47=E47,1) | R47: {=_xlfn.XLOOKUP(B47,'OA名单'!B:B,'OA名单'!F:F)} | S47: =IF(R47=F47,1) | T47: {=_xlfn.XLOOKUP(B47,'系统-原始（副本）'!A:A,'系统-原始（副本）'!B:B)} | U47: {=_xlfn.XLOOKUP(N47,'OA名单'!B:B,'OA名单'!E:E)} | V47: =IF(U47=G47,1)
B48: FD-043242 | C48: 26年 | D48: 7月 | E48: 品牌创意部 | F48: 直播中心 | G48: 直播助理 | H48: 刘韵莹 | I48: 0.98615 | J48: 98.62 | K48: =K48:J48% | L48: 1500 | M48: 1000 | N48: {=_xlfn.XLOOKUP(H48,'OA名单'!C:C,'OA名单'!B:B,1)} | O48: =IF(N48=B48,1) | P48: {=_xlfn.XLOOKUP(N48,'OA名单'!B:B,'OA名单'!G:G)} | Q48: =IF(P48=E48,1) | R48: {=_xlfn.XLOOKUP(B48,'OA名单'!B:B,'OA名单'!F:F)} | S48: =IF(R48=F48,1) | U48: {=_xlfn.XLOOKUP(N48,'OA名单'!B:B,'OA名单'!E:E)} | V48: =IF(U48=G48,1)
B49: FD-047323 | C49: 26年 | D49: 7月 | E49: 品牌创意部 | F49: 直播中心 | G49: 直播助理 | H49: 秦国鸠 | I49: 0.98565 | J49: 98.57 | K49: =K49:J49% | L49: 1650 | M49: 1000 | N49: {=_xlfn.XLOOKUP(H49,'OA名单'!C:C,'OA名单'!B:B,1)} | O49: =IF(N49=B49,1) | P49: {=_xlfn.XLOOKUP(N49,'OA名单'!B:B,'OA名单'!G:G)} | Q49: =IF(P49=E49,1) | R49: {=_xlfn.XLOOKUP(B49,'OA名单'!B:B,'OA名单'!F:F)} | S49: =IF(R49=F49,1) | T49: {=_xlfn.XLOOKUP(B49,'系统-原始（副本）'!A:A,'系统-原始（副本）'!B:B)} | U49: {=_xlfn.XLOOKUP(N49,'OA名单'!B:B,'OA名单'!E:E)} | V49: =IF(U49=G49,1)
B50: FD-041125 | C50: 26年 | D50: 7月 | E50: 品牌创意部 | F50: 直播中心 | G50: 直播助理 | H50: 刘源 | I50: 0.9853 | J50: 98.53 | K50: =K50:J50% | L50: 1425 | M50: 1000 | N50: {=_xlfn.XLOOKUP(H50,'OA名单'!C:C,'OA名单'!B:B,1)} | O50: =IF(N50=B50,1) | P50: {=_xlfn.XLOOKUP(N50,'OA名单'!B:B,'OA名单'!G:G)} | Q50: =IF(P50=E50,1) | R50: {=_xlfn.XLOOKUP(B50,'OA名单'!B:B,'OA名单'!F:F)} | S50: =IF(R50=F50,1) | U50: {=_xlfn.XLOOKUP(N50,'OA名单'!B:B,'OA名单'!E:E)} | V50: =IF(U50=G50,1)
B51: FD-037854 | C51: 26年 | D51: 7月 | E51: 广告策划部 | F51: 直播A中心 | G51: 直播助理 | H51: 祝愿 | I51: 0.98 | J51: 98.5 | K51: =K51:J51% | L51: 1900 | M51: 1000 | N51: {=_xlfn.XLOOKUP(H51,'OA名单'!C:C,'OA名单'!B:B,1)} | O51: =IF(N51=B51,1) | P51: {=_xlfn.XLOOKUP(N51,'OA名单'!B:B,'OA名单'!G:G)} | Q51: =IF(P51=E51,1) | R51: {=_xlfn.XLOOKUP(B51,'OA名单'!B:B,'OA名单'!F:F)} | S51: =IF(R51=F51,1) | T51: {=_xlfn.XLOOKUP(B51,'系统-原始（副本）'!A:A,'系统-原始（副本）'!B:B)} | U51: {=_xlfn.XLOOKUP(N51,'OA名单'!B:B,'OA名单'!E:E)} | V51: =IF(U51=G51,1)
B52: FD-044987 | C52: 26年 | D52: 7月 | E52: 品牌创意部 | F52: 直播中心 | G52: 直播助理 | H52: 何乐妍 | I52: 0.9844 | J52: 98.44 | K52: =K52:J52% | L52: 1225 | M52: 1000 | N52: {=_xlfn.XLOOKUP(H52,'OA名单'!C:C,'OA名单'!B:B,1)} | O52: =IF(N52=B52,1) | P52: {=_xlfn.XLOOKUP(N52,'OA名单'!B:B,'OA名单'!G:G)} | Q52: =IF(P52=E52,1) | R52: {=_xlfn.XLOOKUP(B52,'OA名单'!B:B,'OA名单'!F:F)} | S52: =IF(R52=F52,1) | U52: {=_xlfn.XLOOKUP(N52,'OA名单'!B:B,'OA名单'!E:E)} | V52: =IF(U52=G52,1)
B53: FD-039959 | C53: 26年 | D53: 7月 | E53: 广告策划部 | F53: 直播A中心 | G53: 直播助理 | H53: 谭程宝 | I53: 0.9782 | J53: 98.32 | K53: =K53:J53% | L53: 1300 | M53: 1000 | N53: {=_xlfn.XLOOKUP(H53,'OA名单'!C:C,'OA名单'!B:B,1)} | O53: =IF(N53=B53,1) | P53: {=_xlfn.XLOOKUP(N53,'OA名单'!B:B,'OA名单'!G:G)} | Q53: =IF(P53=E53,1) | R53: {=_xlfn.XLOOKUP(B53,'OA名单'!B:B,'OA名单'!F:F)} | S53: =IF(R53=F53,1) | U53: {=_xlfn.XLOOKUP(N53,'OA名单'!B:B,'OA名单'!E:E)} | V53: =IF(U53=G53,1)
B54: FD-044428 | C54: 26年 | D54: 7月 | E54: 品牌创意部 | F54: 直播中心 | G54: 直播助理 | H54: 文灿 | I54: 0.9811 | J54: 98.11 | K54: =K54:J54% | L54: 1100 | M54: 1000 | N54: {=_xlfn.XLOOKUP(H54,'OA名单'!C:C,'OA名单'!B:B,1)} | O54: =IF(N54=B54,1) | P54: {=_xlfn.XLOOKUP(N54,'OA名单'!B:B,'OA名单'!G:G)} | Q54: =IF(P54=E54,1) | R54: {=_xlfn.XLOOKUP(B54,'OA名单'!B:B,'OA名单'!F:F)} | S54: =IF(R54=F54,1) | U54: {=_xlfn.XLOOKUP(N54,'OA名单'!B:B,'OA名单'!E:E)} | V54: =IF(U54=G54,1)
B55: FD-030834 | C55: 26年 | D55: 7月 | E55: 广告策划部 | F55: 直播A中心 | G55: 直播助理 | H55: 郑岚珊 | I55: 0.9779 | J55: 98.04 | K55: =K55:J55% | L55: 1600 | M55: 1000 | N55: {=_xlfn.XLOOKUP(H55,'OA名单'!C:C,'OA名单'!B:B,1)} | O55: =IF(N55=B55,1) | P55: {=_xlfn.XLOOKUP(N55,'OA名单'!B:B,'OA名单'!G:G)} | Q55: =IF(P55=E55,1) | R55: {=_xlfn.XLOOKUP(B55,'OA名单'!B:B,'OA名单'!F:F)} | S55: =IF(R55=F55,1) | U55: {=_xlfn.XLOOKUP(N55,'OA名单'!B:B,'OA名单'!E:E)} | V55: =IF(U55=G55,1)
B56: FD-041846 | C56: 26年 | D56: 7月 | E56: 品牌创意部 | F56: 直播中心 | G56: 直播助理 | H56: 王佳豪 | I56: 0.9802 | J56: 98.02 | K56: =K56:J56% | L56: 700 | M56: 1000 | N56: {=_xlfn.XLOOKUP(H56,'OA名单'!C:C,'OA名单'!B:B,1)} | O56: =IF(N56=B56,1) | P56: {=_xlfn.XLOOKUP(N56,'OA名单'!B:B,'OA名单'!G:G)} | Q56: =IF(P56=E56,1) | R56: {=_xlfn.XLOOKUP(B56,'OA名单'!B:B,'OA名单'!F:F)} | S56: =IF(R56=F56,1) | U56: {=_xlfn.XLOOKUP(N56,'OA名单'!B:B,'OA名单'!E:E)} | V56: =IF(U56=G56,1)
